[2024-08-17T13:52:49.132+0000] {taskinstance.py:1956} INFO - Dependencies all met for dep_context=non-requeueable deps ti=<TaskInstance: process_etl_properties.obtain_original_data manual__2024-08-17T13:52:48.636531+00:00 [queued]>
[2024-08-17T13:52:49.135+0000] {taskinstance.py:1956} INFO - Dependencies all met for dep_context=requeueable deps ti=<TaskInstance: process_etl_properties.obtain_original_data manual__2024-08-17T13:52:48.636531+00:00 [queued]>
[2024-08-17T13:52:49.136+0000] {taskinstance.py:2170} INFO - Starting attempt 1 of 2
[2024-08-17T13:52:49.142+0000] {taskinstance.py:2191} INFO - Executing <Task(_PythonVirtualenvDecoratedOperator): obtain_original_data> on 2024-08-17 13:52:48.636531+00:00
[2024-08-17T13:52:49.144+0000] {standard_task_runner.py:60} INFO - Started process 235 to run task
[2024-08-17T13:52:49.146+0000] {standard_task_runner.py:87} INFO - Running: ['***', 'tasks', 'run', 'process_etl_properties', 'obtain_original_data', 'manual__2024-08-17T13:52:48.636531+00:00', '--job-id', '6', '--raw', '--subdir', 'DAGS_FOLDER/etl_properties_process.py', '--cfg-path', '/tmp/tmpnxco53ur']
[2024-08-17T13:52:49.148+0000] {standard_task_runner.py:88} INFO - Job 6: Subtask obtain_original_data
[2024-08-17T13:52:49.174+0000] {task_command.py:423} INFO - Running <TaskInstance: process_etl_properties.obtain_original_data manual__2024-08-17T13:52:48.636531+00:00 [running]> on host 5f2606e33b15
[2024-08-17T13:52:49.216+0000] {taskinstance.py:2480} INFO - Exporting env vars: AIRFLOW_CTX_DAG_OWNER='CEIA TP Final' AIRFLOW_CTX_DAG_ID='process_etl_properties' AIRFLOW_CTX_TASK_ID='obtain_original_data' AIRFLOW_CTX_EXECUTION_DATE='2024-08-17T13:52:48.636531+00:00' AIRFLOW_CTX_TRY_NUMBER='1' AIRFLOW_CTX_DAG_RUN_ID='manual__2024-08-17T13:52:48.636531+00:00'
[2024-08-17T13:52:49.218+0000] {process_utils.py:182} INFO - Executing cmd: /usr/local/bin/python -m virtualenv /tmp/venvwqgkk80e --system-site-packages --python=python
[2024-08-17T13:52:49.223+0000] {process_utils.py:186} INFO - Output:
[2024-08-17T13:52:49.636+0000] {process_utils.py:190} INFO - created virtual environment CPython3.8.18.final.0-64 in 199ms
[2024-08-17T13:52:49.640+0000] {process_utils.py:190} INFO -   creator CPython3Posix(dest=/tmp/venvwqgkk80e, clear=False, no_vcs_ignore=False, global=True)
[2024-08-17T13:52:49.640+0000] {process_utils.py:190} INFO -   seeder FromAppData(download=False, pip=bundle, setuptools=bundle, wheel=bundle, via=copy, app_data_dir=/tmp/tmpg8ufui0u)
[2024-08-17T13:52:49.640+0000] {process_utils.py:190} INFO -     added seed packages: pip==23.3.1, setuptools==69.0.2, wheel==0.42.0
[2024-08-17T13:52:49.641+0000] {process_utils.py:190} INFO -   activators BashActivator,CShellActivator,FishActivator,NushellActivator,PowerShellActivator,PythonActivator
[2024-08-17T13:52:49.661+0000] {process_utils.py:182} INFO - Executing cmd: /tmp/venvwqgkk80e/bin/pip install -r /tmp/venvwqgkk80e/requirements.txt
[2024-08-17T13:52:49.666+0000] {process_utils.py:186} INFO - Output:
[2024-08-17T13:52:50.184+0000] {process_utils.py:190} INFO - WARNING: The directory '/home/***/.cache/pip' or its parent directory is not owned or is not writable by the current user. The cache has been disabled. Check the permissions and owner of that directory. If executing pip with sudo, you should use sudo's -H flag.
[2024-08-17T13:52:51.637+0000] {process_utils.py:190} INFO - Collecting awswrangler==3.6.0 (from -r /tmp/venvwqgkk80e/requirements.txt (line 1))
[2024-08-17T13:52:51.937+0000] {process_utils.py:190} INFO -   Downloading awswrangler-3.6.0-py3-none-any.whl.metadata (23 kB)
[2024-08-17T13:52:51.967+0000] {process_utils.py:190} INFO - Requirement already satisfied: pandas in /home/***/.local/lib/python3.8/site-packages (from -r /tmp/venvwqgkk80e/requirements.txt (line 2)) (2.0.3)
[2024-08-17T13:52:52.136+0000] {process_utils.py:190} INFO - Collecting ucimlrepo==0.0.3 (from -r /tmp/venvwqgkk80e/requirements.txt (line 3))
[2024-08-17T13:52:52.300+0000] {process_utils.py:190} INFO -   Downloading ucimlrepo-0.0.3-py3-none-any.whl.metadata (5.2 kB)
[2024-08-17T13:52:52.342+0000] {process_utils.py:190} INFO - Requirement already satisfied: boto3<2.0.0,>=1.20.32 in /home/***/.local/lib/python3.8/site-packages (from awswrangler==3.6.0->-r /tmp/venvwqgkk80e/requirements.txt (line 1)) (1.34.158)
[2024-08-17T13:52:52.342+0000] {process_utils.py:190} INFO - Requirement already satisfied: botocore<2.0.0,>=1.23.32 in /home/***/.local/lib/python3.8/site-packages (from awswrangler==3.6.0->-r /tmp/venvwqgkk80e/requirements.txt (line 1)) (1.34.158)
[2024-08-17T13:52:52.343+0000] {process_utils.py:190} INFO - Requirement already satisfied: numpy<2.0,>=1.18 in /home/***/.local/lib/python3.8/site-packages (from awswrangler==3.6.0->-r /tmp/venvwqgkk80e/requirements.txt (line 1)) (1.24.4)
[2024-08-17T13:52:52.343+0000] {process_utils.py:190} INFO - Requirement already satisfied: packaging<24.0,>=21.1 in /home/***/.local/lib/python3.8/site-packages (from awswrangler==3.6.0->-r /tmp/venvwqgkk80e/requirements.txt (line 1)) (23.2)
[2024-08-17T13:52:52.344+0000] {process_utils.py:190} INFO - Requirement already satisfied: pyarrow>=7.0.0 in /home/***/.local/lib/python3.8/site-packages (from awswrangler==3.6.0->-r /tmp/venvwqgkk80e/requirements.txt (line 1)) (14.0.2)
[2024-08-17T13:52:52.344+0000] {process_utils.py:190} INFO - Requirement already satisfied: typing-extensions<5.0.0,>=4.4.0 in /home/***/.local/lib/python3.8/site-packages (from awswrangler==3.6.0->-r /tmp/venvwqgkk80e/requirements.txt (line 1)) (4.12.2)
[2024-08-17T13:52:52.379+0000] {process_utils.py:190} INFO - Requirement already satisfied: python-dateutil>=2.8.2 in /home/***/.local/lib/python3.8/site-packages (from pandas->-r /tmp/venvwqgkk80e/requirements.txt (line 2)) (2.8.2)
[2024-08-17T13:52:52.380+0000] {process_utils.py:190} INFO - Requirement already satisfied: pytz>=2020.1 in /home/***/.local/lib/python3.8/site-packages (from pandas->-r /tmp/venvwqgkk80e/requirements.txt (line 2)) (2023.3.post1)
[2024-08-17T13:52:52.380+0000] {process_utils.py:190} INFO - Requirement already satisfied: tzdata>=2022.1 in /home/***/.local/lib/python3.8/site-packages (from pandas->-r /tmp/venvwqgkk80e/requirements.txt (line 2)) (2023.4)
[2024-08-17T13:52:52.383+0000] {process_utils.py:190} INFO - Requirement already satisfied: jmespath<2.0.0,>=0.7.1 in /home/***/.local/lib/python3.8/site-packages (from boto3<2.0.0,>=1.20.32->awswrangler==3.6.0->-r /tmp/venvwqgkk80e/requirements.txt (line 1)) (0.10.0)
[2024-08-17T13:52:52.383+0000] {process_utils.py:190} INFO - Requirement already satisfied: s3transfer<0.11.0,>=0.10.0 in /home/***/.local/lib/python3.8/site-packages (from boto3<2.0.0,>=1.20.32->awswrangler==3.6.0->-r /tmp/venvwqgkk80e/requirements.txt (line 1)) (0.10.2)
[2024-08-17T13:52:52.386+0000] {process_utils.py:190} INFO - Requirement already satisfied: urllib3<1.27,>=1.25.4 in /home/***/.local/lib/python3.8/site-packages (from botocore<2.0.0,>=1.23.32->awswrangler==3.6.0->-r /tmp/venvwqgkk80e/requirements.txt (line 1)) (1.26.18)
[2024-08-17T13:52:52.389+0000] {process_utils.py:190} INFO - Requirement already satisfied: six>=1.5 in /home/***/.local/lib/python3.8/site-packages (from python-dateutil>=2.8.2->pandas->-r /tmp/venvwqgkk80e/requirements.txt (line 2)) (1.16.0)
[2024-08-17T13:52:52.798+0000] {process_utils.py:190} INFO - Downloading awswrangler-3.6.0-py3-none-any.whl (403 kB)
[2024-08-17T13:52:53.378+0000] {process_utils.py:190} INFO -    ━━━━━━━━━━━━━━━━━━━━━━━━━━━━━━━━━━━━━━━ 403.8/403.8 kB 682.0 kB/s eta 0:00:00
[2024-08-17T13:52:53.536+0000] {process_utils.py:190} INFO - Downloading ucimlrepo-0.0.3-py3-none-any.whl (7.0 kB)
[2024-08-17T13:52:54.871+0000] {process_utils.py:190} INFO - Installing collected packages: ucimlrepo, awswrangler
[2024-08-17T13:52:54.987+0000] {process_utils.py:190} INFO - Successfully installed awswrangler-3.6.0 ucimlrepo-0.0.3
[2024-08-17T13:52:55.128+0000] {process_utils.py:190} INFO - 
[2024-08-17T13:52:55.129+0000] {process_utils.py:190} INFO - [notice] A new release of pip is available: 23.3.1 -> 24.2
[2024-08-17T13:52:55.129+0000] {process_utils.py:190} INFO - [notice] To update, run: python -m pip install --upgrade pip
[2024-08-17T13:52:55.204+0000] {process_utils.py:182} INFO - Executing cmd: /tmp/venvwqgkk80e/bin/python /tmp/venv-call3deqpfoy/script.py /tmp/venv-call3deqpfoy/script.in /tmp/venv-call3deqpfoy/script.out /tmp/venv-call3deqpfoy/string_args.txt /tmp/venv-call3deqpfoy/termination.log
[2024-08-17T13:52:55.207+0000] {process_utils.py:186} INFO - Output:
[2024-08-17T13:52:56.034+0000] {process_utils.py:190} INFO - Traceback (most recent call last):
[2024-08-17T13:52:56.034+0000] {process_utils.py:190} INFO -   File "/tmp/venv-call3deqpfoy/script.py", line 46, in <module>
[2024-08-17T13:52:56.034+0000] {process_utils.py:190} INFO -     res = get_data(*arg_dict["args"], **arg_dict["kwargs"])
[2024-08-17T13:52:56.035+0000] {process_utils.py:190} INFO -   File "/tmp/venv-call3deqpfoy/script.py", line 37, in get_data
[2024-08-17T13:52:56.035+0000] {process_utils.py:190} INFO -     origin = pd.read_csv(URL_DATASET)
[2024-08-17T13:52:56.035+0000] {process_utils.py:190} INFO - NameError: name 'pd' is not defined
[2024-08-17T13:52:56.184+0000] {taskinstance.py:2698} ERROR - Task failed with exception
Traceback (most recent call last):
  File "/home/airflow/.local/lib/python3.8/site-packages/airflow/models/taskinstance.py", line 433, in _execute_task
    result = execute_callable(context=context, **execute_callable_kwargs)
  File "/home/airflow/.local/lib/python3.8/site-packages/airflow/decorators/base.py", line 241, in execute
    return_value = super().execute(context)
  File "/home/airflow/.local/lib/python3.8/site-packages/airflow/operators/python.py", line 400, in execute
    return super().execute(context=serializable_context)
  File "/home/airflow/.local/lib/python3.8/site-packages/airflow/operators/python.py", line 199, in execute
    return_value = self.execute_callable()
  File "/home/airflow/.local/lib/python3.8/site-packages/airflow/operators/python.py", line 716, in execute_callable
    result = self._execute_python_callable_in_subprocess(python_path)
  File "/home/airflow/.local/lib/python3.8/site-packages/airflow/operators/python.py", line 471, in _execute_python_callable_in_subprocess
    raise AirflowException(error_msg) from None
airflow.exceptions.AirflowException: Process returned non-zero exit status 1.
name 'pd' is not defined
[2024-08-17T13:52:56.185+0000] {taskinstance.py:1138} INFO - Marking task as UP_FOR_RETRY. dag_id=process_etl_properties, task_id=obtain_original_data, execution_date=20240817T135248, start_date=20240817T135249, end_date=20240817T135256
[2024-08-17T13:52:56.191+0000] {standard_task_runner.py:107} ERROR - Failed to execute job 6 for task obtain_original_data (Process returned non-zero exit status 1.
name 'pd' is not defined; 235)
[2024-08-17T13:52:56.238+0000] {local_task_job_runner.py:234} INFO - Task exited with return code 1
[2024-08-17T13:52:56.245+0000] {taskinstance.py:3280} INFO - 0 downstream tasks scheduled from follow-on schedule check
