[2024-08-13T01:58:56.402+0000] {taskinstance.py:1956} INFO - Dependencies all met for dep_context=non-requeueable deps ti=<TaskInstance: process_etl_heart_data.make_dummies_variables scheduled__2024-08-12T00:00:00+00:00 [queued]>
[2024-08-13T01:58:56.405+0000] {taskinstance.py:1956} INFO - Dependencies all met for dep_context=requeueable deps ti=<TaskInstance: process_etl_heart_data.make_dummies_variables scheduled__2024-08-12T00:00:00+00:00 [queued]>
[2024-08-13T01:58:56.405+0000] {taskinstance.py:2170} INFO - Starting attempt 1 of 2
[2024-08-13T01:58:56.410+0000] {taskinstance.py:2191} INFO - Executing <Task(_PythonVirtualenvDecoratedOperator): make_dummies_variables> on 2024-08-12 00:00:00+00:00
[2024-08-13T01:58:56.412+0000] {standard_task_runner.py:60} INFO - Started process 1213 to run task
[2024-08-13T01:58:56.414+0000] {standard_task_runner.py:87} INFO - Running: ['***', 'tasks', 'run', 'process_etl_heart_data', 'make_dummies_variables', 'scheduled__2024-08-12T00:00:00+00:00', '--job-id', '5', '--raw', '--subdir', 'DAGS_FOLDER/etl_process.py', '--cfg-path', '/tmp/tmppn7n19ly']
[2024-08-13T01:58:56.415+0000] {standard_task_runner.py:88} INFO - Job 5: Subtask make_dummies_variables
[2024-08-13T01:58:56.435+0000] {task_command.py:423} INFO - Running <TaskInstance: process_etl_heart_data.make_dummies_variables scheduled__2024-08-12T00:00:00+00:00 [running]> on host 9c98cbfa0d20
[2024-08-13T01:58:56.464+0000] {taskinstance.py:2480} INFO - Exporting env vars: AIRFLOW_CTX_DAG_OWNER='Facundo Adrian Lucianna' AIRFLOW_CTX_DAG_ID='process_etl_heart_data' AIRFLOW_CTX_TASK_ID='make_dummies_variables' AIRFLOW_CTX_EXECUTION_DATE='2024-08-12T00:00:00+00:00' AIRFLOW_CTX_TRY_NUMBER='1' AIRFLOW_CTX_DAG_RUN_ID='scheduled__2024-08-12T00:00:00+00:00'
[2024-08-13T01:58:56.466+0000] {process_utils.py:182} INFO - Executing cmd: /usr/local/bin/python -m virtualenv /tmp/venvs83ih2zt --system-site-packages --python=python
[2024-08-13T01:58:56.468+0000] {process_utils.py:186} INFO - Output:
[2024-08-13T01:58:56.780+0000] {process_utils.py:190} INFO - created virtual environment CPython3.8.18.final.0-64 in 154ms
[2024-08-13T01:58:56.781+0000] {process_utils.py:190} INFO -   creator CPython3Posix(dest=/tmp/venvs83ih2zt, clear=False, no_vcs_ignore=False, global=True)
[2024-08-13T01:58:56.781+0000] {process_utils.py:190} INFO -   seeder FromAppData(download=False, pip=bundle, setuptools=bundle, wheel=bundle, via=copy, app_data_dir=/tmp/tmp84njl50l)
[2024-08-13T01:58:56.781+0000] {process_utils.py:190} INFO -     added seed packages: pip==23.3.1, setuptools==69.0.2, wheel==0.42.0
[2024-08-13T01:58:56.781+0000] {process_utils.py:190} INFO -   activators BashActivator,CShellActivator,FishActivator,NushellActivator,PowerShellActivator,PythonActivator
[2024-08-13T01:58:56.798+0000] {process_utils.py:182} INFO - Executing cmd: /tmp/venvs83ih2zt/bin/pip install -r /tmp/venvs83ih2zt/requirements.txt
[2024-08-13T01:58:56.801+0000] {process_utils.py:186} INFO - Output:
[2024-08-13T01:58:57.167+0000] {process_utils.py:190} INFO - WARNING: The directory '/home/***/.cache/pip' or its parent directory is not owned or is not writable by the current user. The cache has been disabled. Check the permissions and owner of that directory. If executing pip with sudo, you should use sudo's -H flag.
[2024-08-13T01:58:57.317+0000] {process_utils.py:190} INFO - Collecting awswrangler==3.6.0 (from -r /tmp/venvs83ih2zt/requirements.txt (line 1))
[2024-08-13T01:58:57.359+0000] {process_utils.py:190} INFO -   Downloading awswrangler-3.6.0-py3-none-any.whl.metadata (23 kB)
[2024-08-13T01:58:57.381+0000] {process_utils.py:190} INFO - Requirement already satisfied: boto3<2.0.0,>=1.20.32 in /home/***/.local/lib/python3.8/site-packages (from awswrangler==3.6.0->-r /tmp/venvs83ih2zt/requirements.txt (line 1)) (1.34.158)
[2024-08-13T01:58:57.381+0000] {process_utils.py:190} INFO - Requirement already satisfied: botocore<2.0.0,>=1.23.32 in /home/***/.local/lib/python3.8/site-packages (from awswrangler==3.6.0->-r /tmp/venvs83ih2zt/requirements.txt (line 1)) (1.34.158)
[2024-08-13T01:58:57.381+0000] {process_utils.py:190} INFO - Requirement already satisfied: numpy<2.0,>=1.18 in /home/***/.local/lib/python3.8/site-packages (from awswrangler==3.6.0->-r /tmp/venvs83ih2zt/requirements.txt (line 1)) (1.24.4)
[2024-08-13T01:58:57.382+0000] {process_utils.py:190} INFO - Requirement already satisfied: packaging<24.0,>=21.1 in /home/***/.local/lib/python3.8/site-packages (from awswrangler==3.6.0->-r /tmp/venvs83ih2zt/requirements.txt (line 1)) (23.2)
[2024-08-13T01:58:57.382+0000] {process_utils.py:190} INFO - Requirement already satisfied: pandas<2.1.0,>=1.2.0 in /home/***/.local/lib/python3.8/site-packages (from awswrangler==3.6.0->-r /tmp/venvs83ih2zt/requirements.txt (line 1)) (2.0.3)
[2024-08-13T01:58:57.383+0000] {process_utils.py:190} INFO - Requirement already satisfied: pyarrow>=7.0.0 in /home/***/.local/lib/python3.8/site-packages (from awswrangler==3.6.0->-r /tmp/venvs83ih2zt/requirements.txt (line 1)) (14.0.2)
[2024-08-13T01:58:57.383+0000] {process_utils.py:190} INFO - Requirement already satisfied: typing-extensions<5.0.0,>=4.4.0 in /home/***/.local/lib/python3.8/site-packages (from awswrangler==3.6.0->-r /tmp/venvs83ih2zt/requirements.txt (line 1)) (4.12.2)
[2024-08-13T01:58:57.385+0000] {process_utils.py:190} INFO - Requirement already satisfied: jmespath<2.0.0,>=0.7.1 in /home/***/.local/lib/python3.8/site-packages (from boto3<2.0.0,>=1.20.32->awswrangler==3.6.0->-r /tmp/venvs83ih2zt/requirements.txt (line 1)) (0.10.0)
[2024-08-13T01:58:57.386+0000] {process_utils.py:190} INFO - Requirement already satisfied: s3transfer<0.11.0,>=0.10.0 in /home/***/.local/lib/python3.8/site-packages (from boto3<2.0.0,>=1.20.32->awswrangler==3.6.0->-r /tmp/venvs83ih2zt/requirements.txt (line 1)) (0.10.2)
[2024-08-13T01:58:57.388+0000] {process_utils.py:190} INFO - Requirement already satisfied: python-dateutil<3.0.0,>=2.1 in /home/***/.local/lib/python3.8/site-packages (from botocore<2.0.0,>=1.23.32->awswrangler==3.6.0->-r /tmp/venvs83ih2zt/requirements.txt (line 1)) (2.8.2)
[2024-08-13T01:58:57.389+0000] {process_utils.py:190} INFO - Requirement already satisfied: urllib3<1.27,>=1.25.4 in /home/***/.local/lib/python3.8/site-packages (from botocore<2.0.0,>=1.23.32->awswrangler==3.6.0->-r /tmp/venvs83ih2zt/requirements.txt (line 1)) (1.26.18)
[2024-08-13T01:58:57.423+0000] {process_utils.py:190} INFO - Requirement already satisfied: pytz>=2020.1 in /home/***/.local/lib/python3.8/site-packages (from pandas<2.1.0,>=1.2.0->awswrangler==3.6.0->-r /tmp/venvs83ih2zt/requirements.txt (line 1)) (2023.3.post1)
[2024-08-13T01:58:57.423+0000] {process_utils.py:190} INFO - Requirement already satisfied: tzdata>=2022.1 in /home/***/.local/lib/python3.8/site-packages (from pandas<2.1.0,>=1.2.0->awswrangler==3.6.0->-r /tmp/venvs83ih2zt/requirements.txt (line 1)) (2023.4)
[2024-08-13T01:58:57.427+0000] {process_utils.py:190} INFO - Requirement already satisfied: six>=1.5 in /home/***/.local/lib/python3.8/site-packages (from python-dateutil<3.0.0,>=2.1->botocore<2.0.0,>=1.23.32->awswrangler==3.6.0->-r /tmp/venvs83ih2zt/requirements.txt (line 1)) (1.16.0)
[2024-08-13T01:58:57.448+0000] {process_utils.py:190} INFO - Downloading awswrangler-3.6.0-py3-none-any.whl (403 kB)
[2024-08-13T01:58:57.479+0000] {process_utils.py:190} INFO -    ━━━━━━━━━━━━━━━━━━━━━━━━━━━━━━━━━━━━━━━━ 403.8/403.8 kB 13.6 MB/s eta 0:00:00
[2024-08-13T01:58:58.651+0000] {process_utils.py:190} INFO - Installing collected packages: awswrangler
[2024-08-13T01:58:58.756+0000] {process_utils.py:190} INFO - Successfully installed awswrangler-3.6.0
[2024-08-13T01:58:58.831+0000] {process_utils.py:190} INFO - 
[2024-08-13T01:58:58.831+0000] {process_utils.py:190} INFO - [notice] A new release of pip is available: 23.3.1 -> 24.2
[2024-08-13T01:58:58.831+0000] {process_utils.py:190} INFO - [notice] To update, run: python -m pip install --upgrade pip
[2024-08-13T01:58:58.900+0000] {process_utils.py:182} INFO - Executing cmd: /tmp/venvs83ih2zt/bin/python /tmp/venv-callpqqwhy09/script.py /tmp/venv-callpqqwhy09/script.in /tmp/venv-callpqqwhy09/script.out /tmp/venv-callpqqwhy09/string_args.txt /tmp/venv-callpqqwhy09/termination.log
[2024-08-13T01:58:58.902+0000] {process_utils.py:186} INFO - Output:
[2024-08-13T01:59:00.009+0000] {process_utils.py:190} INFO - [[34m2024-08-13T01:59:00.009+0000[0m] {[34mcredentials.py:[0m1147} INFO[0m - Found credentials in environment variables.[0m
[2024-08-13T01:59:00.042+0000] {process_utils.py:190} INFO - [[34m2024-08-13T01:59:00.042+0000[0m] {[34mconfigprovider.py:[0m952} INFO[0m - Found endpoint for s3 via: environment_service.[0m
[2024-08-13T01:59:00.067+0000] {process_utils.py:190} INFO - [[34m2024-08-13T01:59:00.067+0000[0m] {[34mcredentials.py:[0m1147} INFO[0m - Found credentials in environment variables.[0m
[2024-08-13T01:59:00.096+0000] {process_utils.py:190} INFO - [[34m2024-08-13T01:59:00.096+0000[0m] {[34mconfigprovider.py:[0m952} INFO[0m - Found endpoint for s3 via: environment_service.[0m
[2024-08-13T01:59:00.110+0000] {process_utils.py:190} INFO - [[34m2024-08-13T01:59:00.109+0000[0m] {[34mcredentials.py:[0m1147} INFO[0m - Found credentials in environment variables.[0m
[2024-08-13T01:59:00.134+0000] {process_utils.py:190} INFO - [[34m2024-08-13T01:59:00.134+0000[0m] {[34mconfigprovider.py:[0m952} INFO[0m - Found endpoint for s3 via: environment_service.[0m
[2024-08-13T01:59:00.206+0000] {process_utils.py:190} INFO - [[34m2024-08-13T01:59:00.205+0000[0m] {[34mconnectionpool.py:[0m824} WARNING[0m - Retrying (JitteredRetry(total=4, connect=4, read=5, redirect=5, status=5)) after connection broken by 'NewConnectionError('<urllib3.connection.HTTPConnection object at 0xffff335b89a0>: Failed to establish a new connection: [Errno 111] Connection refused')': /api/2.0/mlflow/experiments/get-by-name?experiment_name=Heart+Disease[0m
[2024-08-13T01:59:04.217+0000] {process_utils.py:190} INFO - [[34m2024-08-13T01:59:04.215+0000[0m] {[34mconnectionpool.py:[0m824} WARNING[0m - Retrying (JitteredRetry(total=3, connect=3, read=5, redirect=5, status=5)) after connection broken by 'NewConnectionError('<urllib3.connection.HTTPConnection object at 0xffff30ea4130>: Failed to establish a new connection: [Errno 111] Connection refused')': /api/2.0/mlflow/experiments/get-by-name?experiment_name=Heart+Disease[0m
[2024-08-13T01:59:12.233+0000] {process_utils.py:190} INFO - [[34m2024-08-13T01:59:12.231+0000[0m] {[34mconnectionpool.py:[0m824} WARNING[0m - Retrying (JitteredRetry(total=2, connect=2, read=5, redirect=5, status=5)) after connection broken by 'NewConnectionError('<urllib3.connection.HTTPConnection object at 0xffff30ea4220>: Failed to establish a new connection: [Errno 111] Connection refused')': /api/2.0/mlflow/experiments/get-by-name?experiment_name=Heart+Disease[0m
[2024-08-13T01:59:28.255+0000] {process_utils.py:190} INFO - [[34m2024-08-13T01:59:28.253+0000[0m] {[34mconnectionpool.py:[0m824} WARNING[0m - Retrying (JitteredRetry(total=1, connect=1, read=5, redirect=5, status=5)) after connection broken by 'NewConnectionError('<urllib3.connection.HTTPConnection object at 0xffff30ea4df0>: Failed to establish a new connection: [Errno 111] Connection refused')': /api/2.0/mlflow/experiments/get-by-name?experiment_name=Heart+Disease[0m
[2024-08-13T02:00:00.271+0000] {process_utils.py:190} INFO - [[34m2024-08-13T02:00:00.269+0000[0m] {[34mconnectionpool.py:[0m824} WARNING[0m - Retrying (JitteredRetry(total=0, connect=0, read=5, redirect=5, status=5)) after connection broken by 'NewConnectionError('<urllib3.connection.HTTPConnection object at 0xffff30ea4c10>: Failed to establish a new connection: [Errno 111] Connection refused')': /api/2.0/mlflow/experiments/get-by-name?experiment_name=Heart+Disease[0m
[2024-08-13T02:00:00.281+0000] {process_utils.py:190} INFO - Traceback (most recent call last):
[2024-08-13T02:00:00.282+0000] {process_utils.py:190} INFO -   File "/home/***/.local/lib/python3.8/site-packages/urllib3/connection.py", line 174, in _new_conn
[2024-08-13T02:00:00.282+0000] {process_utils.py:190} INFO -     conn = connection.create_connection(
[2024-08-13T02:00:00.283+0000] {process_utils.py:190} INFO -   File "/home/***/.local/lib/python3.8/site-packages/urllib3/util/connection.py", line 95, in create_connection
[2024-08-13T02:00:00.283+0000] {process_utils.py:190} INFO -     raise err
[2024-08-13T02:00:00.284+0000] {process_utils.py:190} INFO -   File "/home/***/.local/lib/python3.8/site-packages/urllib3/util/connection.py", line 85, in create_connection
[2024-08-13T02:00:00.284+0000] {process_utils.py:190} INFO -     sock.connect(sa)
[2024-08-13T02:00:00.285+0000] {process_utils.py:190} INFO - ConnectionRefusedError: [Errno 111] Connection refused
[2024-08-13T02:00:00.285+0000] {process_utils.py:190} INFO - 
[2024-08-13T02:00:00.285+0000] {process_utils.py:190} INFO - During handling of the above exception, another exception occurred:
[2024-08-13T02:00:00.286+0000] {process_utils.py:190} INFO - 
[2024-08-13T02:00:00.286+0000] {process_utils.py:190} INFO - Traceback (most recent call last):
[2024-08-13T02:00:00.286+0000] {process_utils.py:190} INFO -   File "/home/***/.local/lib/python3.8/site-packages/urllib3/connectionpool.py", line 715, in urlopen
[2024-08-13T02:00:00.286+0000] {process_utils.py:190} INFO -     httplib_response = self._make_request(
[2024-08-13T02:00:00.287+0000] {process_utils.py:190} INFO -   File "/home/***/.local/lib/python3.8/site-packages/urllib3/connectionpool.py", line 416, in _make_request
[2024-08-13T02:00:00.287+0000] {process_utils.py:190} INFO -     conn.request(method, url, **httplib_request_kw)
[2024-08-13T02:00:00.287+0000] {process_utils.py:190} INFO -   File "/home/***/.local/lib/python3.8/site-packages/urllib3/connection.py", line 244, in request
[2024-08-13T02:00:00.288+0000] {process_utils.py:190} INFO -     super(HTTPConnection, self).request(method, url, body=body, headers=headers)
[2024-08-13T02:00:00.288+0000] {process_utils.py:190} INFO -   File "/usr/local/lib/python3.8/http/client.py", line 1256, in request
[2024-08-13T02:00:00.288+0000] {process_utils.py:190} INFO -     self._send_request(method, url, body, headers, encode_chunked)
[2024-08-13T02:00:00.288+0000] {process_utils.py:190} INFO -   File "/usr/local/lib/python3.8/http/client.py", line 1302, in _send_request
[2024-08-13T02:00:00.289+0000] {process_utils.py:190} INFO -     self.endheaders(body, encode_chunked=encode_chunked)
[2024-08-13T02:00:00.289+0000] {process_utils.py:190} INFO -   File "/usr/local/lib/python3.8/http/client.py", line 1251, in endheaders
[2024-08-13T02:00:00.289+0000] {process_utils.py:190} INFO -     self._send_output(message_body, encode_chunked=encode_chunked)
[2024-08-13T02:00:00.290+0000] {process_utils.py:190} INFO -   File "/usr/local/lib/python3.8/http/client.py", line 1011, in _send_output
[2024-08-13T02:00:00.290+0000] {process_utils.py:190} INFO -     self.send(msg)
[2024-08-13T02:00:00.291+0000] {process_utils.py:190} INFO -   File "/usr/local/lib/python3.8/http/client.py", line 951, in send
[2024-08-13T02:00:00.291+0000] {process_utils.py:190} INFO -     self.connect()
[2024-08-13T02:00:00.291+0000] {process_utils.py:190} INFO -   File "/home/***/.local/lib/python3.8/site-packages/urllib3/connection.py", line 205, in connect
[2024-08-13T02:00:00.292+0000] {process_utils.py:190} INFO -     conn = self._new_conn()
[2024-08-13T02:00:00.292+0000] {process_utils.py:190} INFO -   File "/home/***/.local/lib/python3.8/site-packages/urllib3/connection.py", line 186, in _new_conn
[2024-08-13T02:00:00.292+0000] {process_utils.py:190} INFO -     raise NewConnectionError(
[2024-08-13T02:00:00.293+0000] {process_utils.py:190} INFO - urllib3.exceptions.NewConnectionError: <urllib3.connection.HTTPConnection object at 0xffff30ea4520>: Failed to establish a new connection: [Errno 111] Connection refused
[2024-08-13T02:00:00.293+0000] {process_utils.py:190} INFO - 
[2024-08-13T02:00:00.293+0000] {process_utils.py:190} INFO - During handling of the above exception, another exception occurred:
[2024-08-13T02:00:00.294+0000] {process_utils.py:190} INFO - 
[2024-08-13T02:00:00.294+0000] {process_utils.py:190} INFO - Traceback (most recent call last):
[2024-08-13T02:00:00.294+0000] {process_utils.py:190} INFO -   File "/home/***/.local/lib/python3.8/site-packages/requests/adapters.py", line 486, in send
[2024-08-13T02:00:00.294+0000] {process_utils.py:190} INFO -     resp = conn.urlopen(
[2024-08-13T02:00:00.295+0000] {process_utils.py:190} INFO -   File "/home/***/.local/lib/python3.8/site-packages/urllib3/connectionpool.py", line 827, in urlopen
[2024-08-13T02:00:00.295+0000] {process_utils.py:190} INFO -     return self.urlopen(
[2024-08-13T02:00:00.295+0000] {process_utils.py:190} INFO -   File "/home/***/.local/lib/python3.8/site-packages/urllib3/connectionpool.py", line 827, in urlopen
[2024-08-13T02:00:00.295+0000] {process_utils.py:190} INFO -     return self.urlopen(
[2024-08-13T02:00:00.296+0000] {process_utils.py:190} INFO -   File "/home/***/.local/lib/python3.8/site-packages/urllib3/connectionpool.py", line 827, in urlopen
[2024-08-13T02:00:00.296+0000] {process_utils.py:190} INFO -     return self.urlopen(
[2024-08-13T02:00:00.296+0000] {process_utils.py:190} INFO -   [Previous line repeated 2 more times]
[2024-08-13T02:00:00.296+0000] {process_utils.py:190} INFO -   File "/home/***/.local/lib/python3.8/site-packages/urllib3/connectionpool.py", line 799, in urlopen
[2024-08-13T02:00:00.297+0000] {process_utils.py:190} INFO -     retries = retries.increment(
[2024-08-13T02:00:00.297+0000] {process_utils.py:190} INFO -   File "/home/***/.local/lib/python3.8/site-packages/urllib3/util/retry.py", line 592, in increment
[2024-08-13T02:00:00.297+0000] {process_utils.py:190} INFO -     raise MaxRetryError(_pool, url, error or ResponseError(cause))
[2024-08-13T02:00:00.297+0000] {process_utils.py:190} INFO - urllib3.exceptions.MaxRetryError: HTTPConnectionPool(host='mlflow', port=5005): Max retries exceeded with url: /api/2.0/mlflow/experiments/get-by-name?experiment_name=Heart+Disease (Caused by NewConnectionError('<urllib3.connection.HTTPConnection object at 0xffff30ea4520>: Failed to establish a new connection: [Errno 111] Connection refused'))
[2024-08-13T02:00:00.298+0000] {process_utils.py:190} INFO - 
[2024-08-13T02:00:00.298+0000] {process_utils.py:190} INFO - During handling of the above exception, another exception occurred:
[2024-08-13T02:00:00.298+0000] {process_utils.py:190} INFO - 
[2024-08-13T02:00:00.298+0000] {process_utils.py:190} INFO - Traceback (most recent call last):
[2024-08-13T02:00:00.299+0000] {process_utils.py:190} INFO -   File "/home/***/.local/lib/python3.8/site-packages/mlflow/utils/rest_utils.py", line 187, in http_request
[2024-08-13T02:00:00.299+0000] {process_utils.py:190} INFO -     return _get_http_response_with_retries(
[2024-08-13T02:00:00.299+0000] {process_utils.py:190} INFO -   File "/home/***/.local/lib/python3.8/site-packages/mlflow/utils/request_utils.py", line 237, in _get_http_response_with_retries
[2024-08-13T02:00:00.299+0000] {process_utils.py:190} INFO -     return session.request(method, url, allow_redirects=allow_redirects, **kwargs)
[2024-08-13T02:00:00.300+0000] {process_utils.py:190} INFO -   File "/home/***/.local/lib/python3.8/site-packages/requests/sessions.py", line 589, in request
[2024-08-13T02:00:00.300+0000] {process_utils.py:190} INFO -     resp = self.send(prep, **send_kwargs)
[2024-08-13T02:00:00.300+0000] {process_utils.py:190} INFO -   File "/home/***/.local/lib/python3.8/site-packages/requests/sessions.py", line 703, in send
[2024-08-13T02:00:00.301+0000] {process_utils.py:190} INFO -     r = adapter.send(request, **kwargs)
[2024-08-13T02:00:00.301+0000] {process_utils.py:190} INFO -   File "/home/***/.local/lib/python3.8/site-packages/requests/adapters.py", line 519, in send
[2024-08-13T02:00:00.302+0000] {process_utils.py:190} INFO -     raise ConnectionError(e, request=request)
[2024-08-13T02:00:00.302+0000] {process_utils.py:190} INFO - requests.exceptions.ConnectionError: HTTPConnectionPool(host='mlflow', port=5005): Max retries exceeded with url: /api/2.0/mlflow/experiments/get-by-name?experiment_name=Heart+Disease (Caused by NewConnectionError('<urllib3.connection.HTTPConnection object at 0xffff30ea4520>: Failed to establish a new connection: [Errno 111] Connection refused'))
[2024-08-13T02:00:00.303+0000] {process_utils.py:190} INFO - 
[2024-08-13T02:00:00.303+0000] {process_utils.py:190} INFO - During handling of the above exception, another exception occurred:
[2024-08-13T02:00:00.303+0000] {process_utils.py:190} INFO - 
[2024-08-13T02:00:00.304+0000] {process_utils.py:190} INFO - Traceback (most recent call last):
[2024-08-13T02:00:00.304+0000] {process_utils.py:190} INFO -   File "/tmp/venv-callpqqwhy09/script.py", line 129, in <module>
[2024-08-13T02:00:00.304+0000] {process_utils.py:190} INFO -     res = make_dummies_variables(*arg_dict["args"], **arg_dict["kwargs"])
[2024-08-13T02:00:00.305+0000] {process_utils.py:190} INFO -   File "/tmp/venv-callpqqwhy09/script.py", line 110, in make_dummies_variables
[2024-08-13T02:00:00.305+0000] {process_utils.py:190} INFO -     experiment = mlflow.set_experiment("Heart Disease")
[2024-08-13T02:00:00.305+0000] {process_utils.py:190} INFO -   File "/home/***/.local/lib/python3.8/site-packages/mlflow/tracking/fluent.py", line 143, in set_experiment
[2024-08-13T02:00:00.306+0000] {process_utils.py:190} INFO -     experiment = client.get_experiment_by_name(experiment_name)
[2024-08-13T02:00:00.306+0000] {process_utils.py:190} INFO -   File "/home/***/.local/lib/python3.8/site-packages/mlflow/tracking/client.py", line 1240, in get_experiment_by_name
[2024-08-13T02:00:00.306+0000] {process_utils.py:190} INFO -     return self._tracking_client.get_experiment_by_name(name)
[2024-08-13T02:00:00.306+0000] {process_utils.py:190} INFO -   File "/home/***/.local/lib/python3.8/site-packages/mlflow/tracking/_tracking_service/client.py", line 484, in get_experiment_by_name
[2024-08-13T02:00:00.307+0000] {process_utils.py:190} INFO -     return self.store.get_experiment_by_name(name)
[2024-08-13T02:00:00.307+0000] {process_utils.py:190} INFO -   File "/home/***/.local/lib/python3.8/site-packages/mlflow/store/tracking/rest_store.py", line 518, in get_experiment_by_name
[2024-08-13T02:00:00.307+0000] {process_utils.py:190} INFO -     response_proto = self._call_endpoint(GetExperimentByName, req_body)
[2024-08-13T02:00:00.307+0000] {process_utils.py:190} INFO -   File "/home/***/.local/lib/python3.8/site-packages/mlflow/store/tracking/rest_store.py", line 81, in _call_endpoint
[2024-08-13T02:00:00.307+0000] {process_utils.py:190} INFO -     return call_endpoint(self.get_host_creds(), endpoint, method, json_body, response_proto)
[2024-08-13T02:00:00.308+0000] {process_utils.py:190} INFO -   File "/home/***/.local/lib/python3.8/site-packages/mlflow/utils/rest_utils.py", line 357, in call_endpoint
[2024-08-13T02:00:00.308+0000] {process_utils.py:190} INFO -     response = http_request(**call_kwargs)
[2024-08-13T02:00:00.308+0000] {process_utils.py:190} INFO -   File "/home/***/.local/lib/python3.8/site-packages/mlflow/utils/rest_utils.py", line 210, in http_request
[2024-08-13T02:00:00.308+0000] {process_utils.py:190} INFO -     raise MlflowException(f"API request to {url} failed with exception {e}")
[2024-08-13T02:00:00.309+0000] {process_utils.py:190} INFO - mlflow.exceptions.MlflowException: API request to http://mlflow:5005/api/2.0/mlflow/experiments/get-by-name failed with exception HTTPConnectionPool(host='mlflow', port=5005): Max retries exceeded with url: /api/2.0/mlflow/experiments/get-by-name?experiment_name=Heart+Disease (Caused by NewConnectionError('<urllib3.connection.HTTPConnection object at 0xffff30ea4520>: Failed to establish a new connection: [Errno 111] Connection refused'))
[2024-08-13T02:00:00.540+0000] {taskinstance.py:2698} ERROR - Task failed with exception
Traceback (most recent call last):
  File "/home/airflow/.local/lib/python3.8/site-packages/airflow/models/taskinstance.py", line 433, in _execute_task
    result = execute_callable(context=context, **execute_callable_kwargs)
  File "/home/airflow/.local/lib/python3.8/site-packages/airflow/decorators/base.py", line 241, in execute
    return_value = super().execute(context)
  File "/home/airflow/.local/lib/python3.8/site-packages/airflow/operators/python.py", line 400, in execute
    return super().execute(context=serializable_context)
  File "/home/airflow/.local/lib/python3.8/site-packages/airflow/operators/python.py", line 199, in execute
    return_value = self.execute_callable()
  File "/home/airflow/.local/lib/python3.8/site-packages/airflow/operators/python.py", line 716, in execute_callable
    result = self._execute_python_callable_in_subprocess(python_path)
  File "/home/airflow/.local/lib/python3.8/site-packages/airflow/operators/python.py", line 471, in _execute_python_callable_in_subprocess
    raise AirflowException(error_msg) from None
airflow.exceptions.AirflowException: Process returned non-zero exit status 1.
API request to http://mlflow:5005/api/2.0/mlflow/experiments/get-by-name failed with exception HTTPConnectionPool(host='mlflow', port=5005): Max retries exceeded with url: /api/2.0/mlflow/experiments/get-by-name?experiment_name=Heart+Disease (Caused by NewConnectionError('<urllib3.connection.HTTPConnection object at 0xffff30ea4520>: Failed to establish a new connection: [Errno 111] Connection refused'))
[2024-08-13T02:00:00.542+0000] {taskinstance.py:1138} INFO - Marking task as UP_FOR_RETRY. dag_id=process_etl_heart_data, task_id=make_dummies_variables, execution_date=20240812T000000, start_date=20240813T015856, end_date=20240813T020000
[2024-08-13T02:00:00.551+0000] {standard_task_runner.py:107} ERROR - Failed to execute job 5 for task make_dummies_variables (Process returned non-zero exit status 1.
API request to http://mlflow:5005/api/2.0/mlflow/experiments/get-by-name failed with exception HTTPConnectionPool(host='mlflow', port=5005): Max retries exceeded with url: /api/2.0/mlflow/experiments/get-by-name?experiment_name=Heart+Disease (Caused by NewConnectionError('<urllib3.connection.HTTPConnection object at 0xffff30ea4520>: Failed to establish a new connection: [Errno 111] Connection refused')); 1213)
[2024-08-13T02:00:00.574+0000] {local_task_job_runner.py:234} INFO - Task exited with return code 1
[2024-08-13T02:00:00.587+0000] {taskinstance.py:3280} INFO - 0 downstream tasks scheduled from follow-on schedule check
[2024-08-13T02:05:57.188+0000] {taskinstance.py:1956} INFO - Dependencies all met for dep_context=non-requeueable deps ti=<TaskInstance: process_etl_heart_data.make_dummies_variables scheduled__2024-08-12T00:00:00+00:00 [queued]>
[2024-08-13T02:05:57.191+0000] {taskinstance.py:1956} INFO - Dependencies all met for dep_context=requeueable deps ti=<TaskInstance: process_etl_heart_data.make_dummies_variables scheduled__2024-08-12T00:00:00+00:00 [queued]>
[2024-08-13T02:05:57.192+0000] {taskinstance.py:2170} INFO - Starting attempt 1 of 2
[2024-08-13T02:05:57.197+0000] {taskinstance.py:2191} INFO - Executing <Task(_PythonVirtualenvDecoratedOperator): make_dummies_variables> on 2024-08-12 00:00:00+00:00
[2024-08-13T02:05:57.199+0000] {standard_task_runner.py:60} INFO - Started process 1884 to run task
[2024-08-13T02:05:57.201+0000] {standard_task_runner.py:87} INFO - Running: ['***', 'tasks', 'run', 'process_etl_heart_data', 'make_dummies_variables', 'scheduled__2024-08-12T00:00:00+00:00', '--job-id', '11', '--raw', '--subdir', 'DAGS_FOLDER/etl_process.py', '--cfg-path', '/tmp/tmphvqv76j6']
[2024-08-13T02:05:57.202+0000] {standard_task_runner.py:88} INFO - Job 11: Subtask make_dummies_variables
[2024-08-13T02:05:57.223+0000] {task_command.py:423} INFO - Running <TaskInstance: process_etl_heart_data.make_dummies_variables scheduled__2024-08-12T00:00:00+00:00 [running]> on host 9c98cbfa0d20
[2024-08-13T02:05:57.250+0000] {taskinstance.py:2480} INFO - Exporting env vars: AIRFLOW_CTX_DAG_OWNER='Facundo Adrian Lucianna' AIRFLOW_CTX_DAG_ID='process_etl_heart_data' AIRFLOW_CTX_TASK_ID='make_dummies_variables' AIRFLOW_CTX_EXECUTION_DATE='2024-08-12T00:00:00+00:00' AIRFLOW_CTX_TRY_NUMBER='1' AIRFLOW_CTX_DAG_RUN_ID='scheduled__2024-08-12T00:00:00+00:00'
[2024-08-13T02:05:57.251+0000] {process_utils.py:182} INFO - Executing cmd: /usr/local/bin/python -m virtualenv /tmp/venvqs060b23 --system-site-packages --python=python
[2024-08-13T02:05:57.254+0000] {process_utils.py:186} INFO - Output:
[2024-08-13T02:05:57.546+0000] {process_utils.py:190} INFO - created virtual environment CPython3.8.18.final.0-64 in 135ms
[2024-08-13T02:05:57.546+0000] {process_utils.py:190} INFO -   creator CPython3Posix(dest=/tmp/venvqs060b23, clear=False, no_vcs_ignore=False, global=True)
[2024-08-13T02:05:57.547+0000] {process_utils.py:190} INFO -   seeder FromAppData(download=False, pip=bundle, setuptools=bundle, wheel=bundle, via=copy, app_data_dir=/tmp/tmpeamw1fyu)
[2024-08-13T02:05:57.547+0000] {process_utils.py:190} INFO -     added seed packages: pip==23.3.1, setuptools==69.0.2, wheel==0.42.0
[2024-08-13T02:05:57.547+0000] {process_utils.py:190} INFO -   activators BashActivator,CShellActivator,FishActivator,NushellActivator,PowerShellActivator,PythonActivator
[2024-08-13T02:05:57.563+0000] {process_utils.py:182} INFO - Executing cmd: /tmp/venvqs060b23/bin/pip install -r /tmp/venvqs060b23/requirements.txt
[2024-08-13T02:05:57.565+0000] {process_utils.py:186} INFO - Output:
[2024-08-13T02:05:57.947+0000] {process_utils.py:190} INFO - WARNING: The directory '/home/***/.cache/pip' or its parent directory is not owned or is not writable by the current user. The cache has been disabled. Check the permissions and owner of that directory. If executing pip with sudo, you should use sudo's -H flag.
[2024-08-13T02:05:58.088+0000] {process_utils.py:190} INFO - Collecting awswrangler==3.6.0 (from -r /tmp/venvqs060b23/requirements.txt (line 1))
[2024-08-13T02:05:58.126+0000] {process_utils.py:190} INFO -   Downloading awswrangler-3.6.0-py3-none-any.whl.metadata (23 kB)
[2024-08-13T02:05:58.150+0000] {process_utils.py:190} INFO - Requirement already satisfied: boto3<2.0.0,>=1.20.32 in /home/***/.local/lib/python3.8/site-packages (from awswrangler==3.6.0->-r /tmp/venvqs060b23/requirements.txt (line 1)) (1.34.158)
[2024-08-13T02:05:58.150+0000] {process_utils.py:190} INFO - Requirement already satisfied: botocore<2.0.0,>=1.23.32 in /home/***/.local/lib/python3.8/site-packages (from awswrangler==3.6.0->-r /tmp/venvqs060b23/requirements.txt (line 1)) (1.34.158)
[2024-08-13T02:05:58.151+0000] {process_utils.py:190} INFO - Requirement already satisfied: numpy<2.0,>=1.18 in /home/***/.local/lib/python3.8/site-packages (from awswrangler==3.6.0->-r /tmp/venvqs060b23/requirements.txt (line 1)) (1.24.4)
[2024-08-13T02:05:58.151+0000] {process_utils.py:190} INFO - Requirement already satisfied: packaging<24.0,>=21.1 in /home/***/.local/lib/python3.8/site-packages (from awswrangler==3.6.0->-r /tmp/venvqs060b23/requirements.txt (line 1)) (23.2)
[2024-08-13T02:05:58.151+0000] {process_utils.py:190} INFO - Requirement already satisfied: pandas<2.1.0,>=1.2.0 in /home/***/.local/lib/python3.8/site-packages (from awswrangler==3.6.0->-r /tmp/venvqs060b23/requirements.txt (line 1)) (2.0.3)
[2024-08-13T02:05:58.152+0000] {process_utils.py:190} INFO - Requirement already satisfied: pyarrow>=7.0.0 in /home/***/.local/lib/python3.8/site-packages (from awswrangler==3.6.0->-r /tmp/venvqs060b23/requirements.txt (line 1)) (14.0.2)
[2024-08-13T02:05:58.152+0000] {process_utils.py:190} INFO - Requirement already satisfied: typing-extensions<5.0.0,>=4.4.0 in /home/***/.local/lib/python3.8/site-packages (from awswrangler==3.6.0->-r /tmp/venvqs060b23/requirements.txt (line 1)) (4.12.2)
[2024-08-13T02:05:58.154+0000] {process_utils.py:190} INFO - Requirement already satisfied: jmespath<2.0.0,>=0.7.1 in /home/***/.local/lib/python3.8/site-packages (from boto3<2.0.0,>=1.20.32->awswrangler==3.6.0->-r /tmp/venvqs060b23/requirements.txt (line 1)) (0.10.0)
[2024-08-13T02:05:58.155+0000] {process_utils.py:190} INFO - Requirement already satisfied: s3transfer<0.11.0,>=0.10.0 in /home/***/.local/lib/python3.8/site-packages (from boto3<2.0.0,>=1.20.32->awswrangler==3.6.0->-r /tmp/venvqs060b23/requirements.txt (line 1)) (0.10.2)
[2024-08-13T02:05:58.157+0000] {process_utils.py:190} INFO - Requirement already satisfied: python-dateutil<3.0.0,>=2.1 in /home/***/.local/lib/python3.8/site-packages (from botocore<2.0.0,>=1.23.32->awswrangler==3.6.0->-r /tmp/venvqs060b23/requirements.txt (line 1)) (2.8.2)
[2024-08-13T02:05:58.158+0000] {process_utils.py:190} INFO - Requirement already satisfied: urllib3<1.27,>=1.25.4 in /home/***/.local/lib/python3.8/site-packages (from botocore<2.0.0,>=1.23.32->awswrangler==3.6.0->-r /tmp/venvqs060b23/requirements.txt (line 1)) (1.26.18)
[2024-08-13T02:05:58.191+0000] {process_utils.py:190} INFO - Requirement already satisfied: pytz>=2020.1 in /home/***/.local/lib/python3.8/site-packages (from pandas<2.1.0,>=1.2.0->awswrangler==3.6.0->-r /tmp/venvqs060b23/requirements.txt (line 1)) (2023.3.post1)
[2024-08-13T02:05:58.192+0000] {process_utils.py:190} INFO - Requirement already satisfied: tzdata>=2022.1 in /home/***/.local/lib/python3.8/site-packages (from pandas<2.1.0,>=1.2.0->awswrangler==3.6.0->-r /tmp/venvqs060b23/requirements.txt (line 1)) (2023.4)
[2024-08-13T02:05:58.195+0000] {process_utils.py:190} INFO - Requirement already satisfied: six>=1.5 in /home/***/.local/lib/python3.8/site-packages (from python-dateutil<3.0.0,>=2.1->botocore<2.0.0,>=1.23.32->awswrangler==3.6.0->-r /tmp/venvqs060b23/requirements.txt (line 1)) (1.16.0)
[2024-08-13T02:05:58.218+0000] {process_utils.py:190} INFO - Downloading awswrangler-3.6.0-py3-none-any.whl (403 kB)
[2024-08-13T02:05:58.244+0000] {process_utils.py:190} INFO -    ━━━━━━━━━━━━━━━━━━━━━━━━━━━━━━━━━━━━━━━━ 403.8/403.8 kB 16.2 MB/s eta 0:00:00
[2024-08-13T02:05:59.431+0000] {process_utils.py:190} INFO - Installing collected packages: awswrangler
[2024-08-13T02:05:59.535+0000] {process_utils.py:190} INFO - Successfully installed awswrangler-3.6.0
[2024-08-13T02:05:59.604+0000] {process_utils.py:190} INFO - 
[2024-08-13T02:05:59.605+0000] {process_utils.py:190} INFO - [notice] A new release of pip is available: 23.3.1 -> 24.2
[2024-08-13T02:05:59.605+0000] {process_utils.py:190} INFO - [notice] To update, run: python -m pip install --upgrade pip
[2024-08-13T02:05:59.662+0000] {process_utils.py:182} INFO - Executing cmd: /tmp/venvqs060b23/bin/python /tmp/venv-callol67tx_w/script.py /tmp/venv-callol67tx_w/script.in /tmp/venv-callol67tx_w/script.out /tmp/venv-callol67tx_w/string_args.txt /tmp/venv-callol67tx_w/termination.log
[2024-08-13T02:05:59.664+0000] {process_utils.py:186} INFO - Output:
[2024-08-13T02:06:00.651+0000] {process_utils.py:190} INFO - [[34m2024-08-13T02:06:00.650+0000[0m] {[34mcredentials.py:[0m1147} INFO[0m - Found credentials in environment variables.[0m
[2024-08-13T02:06:00.676+0000] {process_utils.py:190} INFO - [[34m2024-08-13T02:06:00.676+0000[0m] {[34mconfigprovider.py:[0m952} INFO[0m - Found endpoint for s3 via: environment_service.[0m
[2024-08-13T02:06:00.699+0000] {process_utils.py:190} INFO - [[34m2024-08-13T02:06:00.698+0000[0m] {[34mcredentials.py:[0m1147} INFO[0m - Found credentials in environment variables.[0m
[2024-08-13T02:06:00.723+0000] {process_utils.py:190} INFO - [[34m2024-08-13T02:06:00.723+0000[0m] {[34mconfigprovider.py:[0m952} INFO[0m - Found endpoint for s3 via: environment_service.[0m
[2024-08-13T02:06:00.739+0000] {process_utils.py:190} INFO - [[34m2024-08-13T02:06:00.738+0000[0m] {[34mcredentials.py:[0m1147} INFO[0m - Found credentials in environment variables.[0m
[2024-08-13T02:06:00.763+0000] {process_utils.py:190} INFO - [[34m2024-08-13T02:06:00.763+0000[0m] {[34mconfigprovider.py:[0m952} INFO[0m - Found endpoint for s3 via: environment_service.[0m
[2024-08-13T02:06:00.839+0000] {process_utils.py:190} INFO - [[34m2024-08-13T02:06:00.839+0000[0m] {[34mconnectionpool.py:[0m824} WARNING[0m - Retrying (JitteredRetry(total=4, connect=4, read=5, redirect=5, status=5)) after connection broken by 'NewConnectionError('<urllib3.connection.HTTPConnection object at 0xffff28dd29a0>: Failed to establish a new connection: [Errno 111] Connection refused')': /api/2.0/mlflow/experiments/get-by-name?experiment_name=Heart+Disease[0m
[2024-08-13T02:06:04.847+0000] {process_utils.py:190} INFO - [[34m2024-08-13T02:06:04.846+0000[0m] {[34mconnectionpool.py:[0m824} WARNING[0m - Retrying (JitteredRetry(total=3, connect=3, read=5, redirect=5, status=5)) after connection broken by 'NewConnectionError('<urllib3.connection.HTTPConnection object at 0xffff26749fd0>: Failed to establish a new connection: [Errno 111] Connection refused')': /api/2.0/mlflow/experiments/get-by-name?experiment_name=Heart+Disease[0m
[2024-08-13T02:06:12.864+0000] {process_utils.py:190} INFO - [[34m2024-08-13T02:06:12.862+0000[0m] {[34mconnectionpool.py:[0m824} WARNING[0m - Retrying (JitteredRetry(total=2, connect=2, read=5, redirect=5, status=5)) after connection broken by 'NewConnectionError('<urllib3.connection.HTTPConnection object at 0xffff26749cd0>: Failed to establish a new connection: [Errno 111] Connection refused')': /api/2.0/mlflow/experiments/get-by-name?experiment_name=Heart+Disease[0m
[2024-08-13T02:06:28.890+0000] {process_utils.py:190} INFO - [[34m2024-08-13T02:06:28.888+0000[0m] {[34mconnectionpool.py:[0m824} WARNING[0m - Retrying (JitteredRetry(total=1, connect=1, read=5, redirect=5, status=5)) after connection broken by 'NewConnectionError('<urllib3.connection.HTTPConnection object at 0xffff26749e80>: Failed to establish a new connection: [Errno 111] Connection refused')': /api/2.0/mlflow/experiments/get-by-name?experiment_name=Heart+Disease[0m
[2024-08-13T02:06:47.650+0000] {local_task_job_runner.py:302} WARNING - State of this instance has been externally set to failed. Terminating instance.
[2024-08-13T02:06:47.652+0000] {process_utils.py:131} INFO - Sending 15 to group 1884. PIDs of all processes in the group: [1912, 1884]
[2024-08-13T02:06:47.652+0000] {process_utils.py:86} INFO - Sending the signal 15 to group 1884
[2024-08-13T02:06:47.653+0000] {taskinstance.py:2450} ERROR - Received SIGTERM. Terminating subprocesses.
[2024-08-13T02:06:47.660+0000] {process_utils.py:79} INFO - Process psutil.Process(pid=1912, status='terminated', started='02:05:58') (1912) terminated with exit code None
[2024-08-13T02:06:47.693+0000] {process_utils.py:79} INFO - Process psutil.Process(pid=1884, status='terminated', exitcode=0, started='02:05:56') (1884) terminated with exit code 0
[2024-08-13T02:58:43.615+0000] {taskinstance.py:1956} INFO - Dependencies all met for dep_context=non-requeueable deps ti=<TaskInstance: process_etl_heart_data.make_dummies_variables scheduled__2024-08-12T00:00:00+00:00 [queued]>
[2024-08-13T02:58:43.618+0000] {taskinstance.py:1956} INFO - Dependencies all met for dep_context=requeueable deps ti=<TaskInstance: process_etl_heart_data.make_dummies_variables scheduled__2024-08-12T00:00:00+00:00 [queued]>
[2024-08-13T02:58:43.619+0000] {taskinstance.py:2170} INFO - Starting attempt 1 of 2
[2024-08-13T02:58:43.624+0000] {taskinstance.py:2191} INFO - Executing <Task(_PythonVirtualenvDecoratedOperator): make_dummies_variables> on 2024-08-12 00:00:00+00:00
[2024-08-13T02:58:43.626+0000] {standard_task_runner.py:60} INFO - Started process 594 to run task
[2024-08-13T02:58:43.628+0000] {standard_task_runner.py:87} INFO - Running: ['***', 'tasks', 'run', 'process_etl_heart_data', 'make_dummies_variables', 'scheduled__2024-08-12T00:00:00+00:00', '--job-id', '3', '--raw', '--subdir', 'DAGS_FOLDER/etl_process.py', '--cfg-path', '/tmp/tmpsorbaufm']
[2024-08-13T02:58:43.629+0000] {standard_task_runner.py:88} INFO - Job 3: Subtask make_dummies_variables
[2024-08-13T02:58:43.649+0000] {task_command.py:423} INFO - Running <TaskInstance: process_etl_heart_data.make_dummies_variables scheduled__2024-08-12T00:00:00+00:00 [running]> on host 47ccda1db683
[2024-08-13T02:58:43.675+0000] {taskinstance.py:2480} INFO - Exporting env vars: AIRFLOW_CTX_DAG_OWNER='Facundo Adrian Lucianna' AIRFLOW_CTX_DAG_ID='process_etl_heart_data' AIRFLOW_CTX_TASK_ID='make_dummies_variables' AIRFLOW_CTX_EXECUTION_DATE='2024-08-12T00:00:00+00:00' AIRFLOW_CTX_TRY_NUMBER='1' AIRFLOW_CTX_DAG_RUN_ID='scheduled__2024-08-12T00:00:00+00:00'
[2024-08-13T02:58:43.676+0000] {process_utils.py:182} INFO - Executing cmd: /usr/local/bin/python -m virtualenv /tmp/venvb7ckrcx8 --system-site-packages --python=python
[2024-08-13T02:58:43.679+0000] {process_utils.py:186} INFO - Output:
[2024-08-13T02:58:43.970+0000] {process_utils.py:190} INFO - created virtual environment CPython3.8.18.final.0-64 in 139ms
[2024-08-13T02:58:43.970+0000] {process_utils.py:190} INFO -   creator CPython3Posix(dest=/tmp/venvb7ckrcx8, clear=False, no_vcs_ignore=False, global=True)
[2024-08-13T02:58:43.970+0000] {process_utils.py:190} INFO -   seeder FromAppData(download=False, pip=bundle, setuptools=bundle, wheel=bundle, via=copy, app_data_dir=/tmp/tmppxd81zk4)
[2024-08-13T02:58:43.971+0000] {process_utils.py:190} INFO -     added seed packages: pip==23.3.1, setuptools==69.0.2, wheel==0.42.0
[2024-08-13T02:58:43.971+0000] {process_utils.py:190} INFO -   activators BashActivator,CShellActivator,FishActivator,NushellActivator,PowerShellActivator,PythonActivator
[2024-08-13T02:58:43.988+0000] {process_utils.py:182} INFO - Executing cmd: /tmp/venvb7ckrcx8/bin/pip install -r /tmp/venvb7ckrcx8/requirements.txt
[2024-08-13T02:58:43.990+0000] {process_utils.py:186} INFO - Output:
[2024-08-13T02:58:44.355+0000] {process_utils.py:190} INFO - WARNING: The directory '/home/***/.cache/pip' or its parent directory is not owned or is not writable by the current user. The cache has been disabled. Check the permissions and owner of that directory. If executing pip with sudo, you should use sudo's -H flag.
[2024-08-13T02:58:44.495+0000] {process_utils.py:190} INFO - Collecting awswrangler==3.6.0 (from -r /tmp/venvb7ckrcx8/requirements.txt (line 1))
[2024-08-13T02:58:44.535+0000] {process_utils.py:190} INFO -   Downloading awswrangler-3.6.0-py3-none-any.whl.metadata (23 kB)
[2024-08-13T02:58:44.555+0000] {process_utils.py:190} INFO - Requirement already satisfied: boto3<2.0.0,>=1.20.32 in /home/***/.local/lib/python3.8/site-packages (from awswrangler==3.6.0->-r /tmp/venvb7ckrcx8/requirements.txt (line 1)) (1.34.158)
[2024-08-13T02:58:44.555+0000] {process_utils.py:190} INFO - Requirement already satisfied: botocore<2.0.0,>=1.23.32 in /home/***/.local/lib/python3.8/site-packages (from awswrangler==3.6.0->-r /tmp/venvb7ckrcx8/requirements.txt (line 1)) (1.34.158)
[2024-08-13T02:58:44.556+0000] {process_utils.py:190} INFO - Requirement already satisfied: numpy<2.0,>=1.18 in /home/***/.local/lib/python3.8/site-packages (from awswrangler==3.6.0->-r /tmp/venvb7ckrcx8/requirements.txt (line 1)) (1.24.4)
[2024-08-13T02:58:44.556+0000] {process_utils.py:190} INFO - Requirement already satisfied: packaging<24.0,>=21.1 in /home/***/.local/lib/python3.8/site-packages (from awswrangler==3.6.0->-r /tmp/venvb7ckrcx8/requirements.txt (line 1)) (23.2)
[2024-08-13T02:58:44.557+0000] {process_utils.py:190} INFO - Requirement already satisfied: pandas<2.1.0,>=1.2.0 in /home/***/.local/lib/python3.8/site-packages (from awswrangler==3.6.0->-r /tmp/venvb7ckrcx8/requirements.txt (line 1)) (2.0.3)
[2024-08-13T02:58:44.557+0000] {process_utils.py:190} INFO - Requirement already satisfied: pyarrow>=7.0.0 in /home/***/.local/lib/python3.8/site-packages (from awswrangler==3.6.0->-r /tmp/venvb7ckrcx8/requirements.txt (line 1)) (14.0.2)
[2024-08-13T02:58:44.558+0000] {process_utils.py:190} INFO - Requirement already satisfied: typing-extensions<5.0.0,>=4.4.0 in /home/***/.local/lib/python3.8/site-packages (from awswrangler==3.6.0->-r /tmp/venvb7ckrcx8/requirements.txt (line 1)) (4.12.2)
[2024-08-13T02:58:44.560+0000] {process_utils.py:190} INFO - Requirement already satisfied: jmespath<2.0.0,>=0.7.1 in /home/***/.local/lib/python3.8/site-packages (from boto3<2.0.0,>=1.20.32->awswrangler==3.6.0->-r /tmp/venvb7ckrcx8/requirements.txt (line 1)) (0.10.0)
[2024-08-13T02:58:44.560+0000] {process_utils.py:190} INFO - Requirement already satisfied: s3transfer<0.11.0,>=0.10.0 in /home/***/.local/lib/python3.8/site-packages (from boto3<2.0.0,>=1.20.32->awswrangler==3.6.0->-r /tmp/venvb7ckrcx8/requirements.txt (line 1)) (0.10.2)
[2024-08-13T02:58:44.563+0000] {process_utils.py:190} INFO - Requirement already satisfied: python-dateutil<3.0.0,>=2.1 in /home/***/.local/lib/python3.8/site-packages (from botocore<2.0.0,>=1.23.32->awswrangler==3.6.0->-r /tmp/venvb7ckrcx8/requirements.txt (line 1)) (2.8.2)
[2024-08-13T02:58:44.563+0000] {process_utils.py:190} INFO - Requirement already satisfied: urllib3<1.27,>=1.25.4 in /home/***/.local/lib/python3.8/site-packages (from botocore<2.0.0,>=1.23.32->awswrangler==3.6.0->-r /tmp/venvb7ckrcx8/requirements.txt (line 1)) (1.26.18)
[2024-08-13T02:58:44.597+0000] {process_utils.py:190} INFO - Requirement already satisfied: pytz>=2020.1 in /home/***/.local/lib/python3.8/site-packages (from pandas<2.1.0,>=1.2.0->awswrangler==3.6.0->-r /tmp/venvb7ckrcx8/requirements.txt (line 1)) (2023.3.post1)
[2024-08-13T02:58:44.597+0000] {process_utils.py:190} INFO - Requirement already satisfied: tzdata>=2022.1 in /home/***/.local/lib/python3.8/site-packages (from pandas<2.1.0,>=1.2.0->awswrangler==3.6.0->-r /tmp/venvb7ckrcx8/requirements.txt (line 1)) (2023.4)
[2024-08-13T02:58:44.600+0000] {process_utils.py:190} INFO - Requirement already satisfied: six>=1.5 in /home/***/.local/lib/python3.8/site-packages (from python-dateutil<3.0.0,>=2.1->botocore<2.0.0,>=1.23.32->awswrangler==3.6.0->-r /tmp/venvb7ckrcx8/requirements.txt (line 1)) (1.16.0)
[2024-08-13T02:58:44.622+0000] {process_utils.py:190} INFO - Downloading awswrangler-3.6.0-py3-none-any.whl (403 kB)
[2024-08-13T02:58:44.646+0000] {process_utils.py:190} INFO -    ━━━━━━━━━━━━━━━━━━━━━━━━━━━━━━━━━━━━━━━━ 403.8/403.8 kB 17.5 MB/s eta 0:00:00
[2024-08-13T02:58:45.827+0000] {process_utils.py:190} INFO - Installing collected packages: awswrangler
[2024-08-13T02:58:45.928+0000] {process_utils.py:190} INFO - Successfully installed awswrangler-3.6.0
[2024-08-13T02:58:45.994+0000] {process_utils.py:190} INFO - 
[2024-08-13T02:58:45.994+0000] {process_utils.py:190} INFO - [notice] A new release of pip is available: 23.3.1 -> 24.2
[2024-08-13T02:58:45.995+0000] {process_utils.py:190} INFO - [notice] To update, run: python -m pip install --upgrade pip
[2024-08-13T02:58:46.065+0000] {process_utils.py:182} INFO - Executing cmd: /tmp/venvb7ckrcx8/bin/python /tmp/venv-callqkp5i_mc/script.py /tmp/venv-callqkp5i_mc/script.in /tmp/venv-callqkp5i_mc/script.out /tmp/venv-callqkp5i_mc/string_args.txt /tmp/venv-callqkp5i_mc/termination.log
[2024-08-13T02:58:46.069+0000] {process_utils.py:186} INFO - Output:
[2024-08-13T02:58:47.099+0000] {process_utils.py:190} INFO - [[34m2024-08-13T02:58:47.099+0000[0m] {[34mcredentials.py:[0m1147} INFO[0m - Found credentials in environment variables.[0m
[2024-08-13T02:58:47.125+0000] {process_utils.py:190} INFO - [[34m2024-08-13T02:58:47.125+0000[0m] {[34mconfigprovider.py:[0m952} INFO[0m - Found endpoint for s3 via: environment_service.[0m
[2024-08-13T02:58:47.148+0000] {process_utils.py:190} INFO - [[34m2024-08-13T02:58:47.147+0000[0m] {[34mcredentials.py:[0m1147} INFO[0m - Found credentials in environment variables.[0m
[2024-08-13T02:58:47.173+0000] {process_utils.py:190} INFO - [[34m2024-08-13T02:58:47.173+0000[0m] {[34mconfigprovider.py:[0m952} INFO[0m - Found endpoint for s3 via: environment_service.[0m
[2024-08-13T02:58:47.186+0000] {process_utils.py:190} INFO - [[34m2024-08-13T02:58:47.186+0000[0m] {[34mcredentials.py:[0m1147} INFO[0m - Found credentials in environment variables.[0m
[2024-08-13T02:58:47.211+0000] {process_utils.py:190} INFO - [[34m2024-08-13T02:58:47.210+0000[0m] {[34mconfigprovider.py:[0m952} INFO[0m - Found endpoint for s3 via: environment_service.[0m
[2024-08-13T02:58:47.287+0000] {process_utils.py:190} INFO - 2024/08/13 02:58:47 INFO mlflow.tracking.fluent: Experiment with name 'Heart Disease' does not exist. Creating a new experiment.
[2024-08-13T02:58:47.347+0000] {process_utils.py:190} INFO - 2024/08/13 02:58:47 WARNING mlflow.system_metrics.system_metrics_monitor: Skip logging GPU metrics because creating `GPUMonitor` failed with error: `pynvml` is not installed, to log GPU metrics please run `pip install pynvml` to install it..
[2024-08-13T02:58:47.348+0000] {process_utils.py:190} INFO - 2024/08/13 02:58:47 INFO mlflow.system_metrics.system_metrics_monitor: Started monitoring system metrics.
[2024-08-13T02:58:47.362+0000] {process_utils.py:190} INFO - /home/***/.local/lib/python3.8/site-packages/mlflow/data/dataset_source_registry.py:150 UserWarning: Failed to determine whether UCVolumeDatasetSource can resolve source information for 'https://archive.ics.uci.edu/dataset/45/heart+disease'. Exception:
[2024-08-13T02:58:47.366+0000] {process_utils.py:190} INFO - /home/***/.local/lib/python3.8/site-packages/mlflow/data/dataset_source_registry.py:150 UserWarning: Failed to determine whether UCVolumeDatasetSource can resolve source information for 'https://archive.ics.uci.edu/dataset/45/heart+disease'. Exception:
[2024-08-13T02:58:47.369+0000] {process_utils.py:190} INFO - /home/***/.local/lib/python3.8/site-packages/mlflow/types/utils.py:406 UserWarning: Hint: Inferred schema contains integer column(s). Integer columns in Python cannot represent missing values. If your input data contains missing values at inference time, it will be encoded as floats and will cause a schema enforcement error. The best way to avoid this problem is to infer the model schema based on a realistic data sample (training dataset) that includes missing values. Alternatively, you can declare integer columns as doubles (float64) whenever these columns may have missing values. See `Handling Integers With Missing Values <https://www.mlflow.org/docs/latest/models.html#handling-integers-with-missing-values>`_ for more details.
[2024-08-13T02:58:47.394+0000] {process_utils.py:190} INFO - 2024/08/13 02:58:47 INFO mlflow.tracking._tracking_service.client: 🏃 View run ETL_run_2024/08/13-02:58:47" at: http://mlflow:5005/#/experiments/1/runs/ed839609d5c8441894a0bfca99a6d6bd.
[2024-08-13T02:58:47.395+0000] {process_utils.py:190} INFO - 2024/08/13 02:58:47 INFO mlflow.tracking._tracking_service.client: 🧪 View experiment at: http://mlflow:5005/#/experiments/1.
[2024-08-13T02:58:47.402+0000] {process_utils.py:190} INFO - 2024/08/13 02:58:47 INFO mlflow.system_metrics.system_metrics_monitor: Stopping system metrics monitoring...
[2024-08-13T02:58:47.412+0000] {process_utils.py:190} INFO - 2024/08/13 02:58:47 INFO mlflow.system_metrics.system_metrics_monitor: Successfully terminated system metrics monitoring!
[2024-08-13T02:58:47.620+0000] {python.py:201} INFO - Done. Returned value was: None
[2024-08-13T02:58:47.626+0000] {taskinstance.py:1138} INFO - Marking task as SUCCESS. dag_id=process_etl_heart_data, task_id=make_dummies_variables, execution_date=20240812T000000, start_date=20240813T025843, end_date=20240813T025847
[2024-08-13T02:58:47.667+0000] {local_task_job_runner.py:234} INFO - Task exited with return code 0
[2024-08-13T02:58:47.681+0000] {taskinstance.py:3280} INFO - 1 downstream tasks scheduled from follow-on schedule check
[2024-08-13T23:06:42.141+0000] {taskinstance.py:1956} INFO - Dependencies all met for dep_context=non-requeueable deps ti=<TaskInstance: process_etl_heart_data.make_dummies_variables scheduled__2024-08-12T00:00:00+00:00 [queued]>
[2024-08-13T23:06:42.146+0000] {taskinstance.py:1956} INFO - Dependencies all met for dep_context=requeueable deps ti=<TaskInstance: process_etl_heart_data.make_dummies_variables scheduled__2024-08-12T00:00:00+00:00 [queued]>
[2024-08-13T23:06:42.146+0000] {taskinstance.py:2170} INFO - Starting attempt 1 of 2
[2024-08-13T23:06:42.152+0000] {taskinstance.py:2191} INFO - Executing <Task(_PythonVirtualenvDecoratedOperator): make_dummies_variables> on 2024-08-12 00:00:00+00:00
[2024-08-13T23:06:42.154+0000] {standard_task_runner.py:60} INFO - Started process 643 to run task
[2024-08-13T23:06:42.155+0000] {standard_task_runner.py:87} INFO - Running: ['***', 'tasks', 'run', 'process_etl_heart_data', 'make_dummies_variables', 'scheduled__2024-08-12T00:00:00+00:00', '--job-id', '4', '--raw', '--subdir', 'DAGS_FOLDER/etl_process.py', '--cfg-path', '/tmp/tmp5qxnv4md']
[2024-08-13T23:06:42.156+0000] {standard_task_runner.py:88} INFO - Job 4: Subtask make_dummies_variables
[2024-08-13T23:06:42.179+0000] {task_command.py:423} INFO - Running <TaskInstance: process_etl_heart_data.make_dummies_variables scheduled__2024-08-12T00:00:00+00:00 [running]> on host 724c87fe0c82
[2024-08-13T23:06:42.212+0000] {taskinstance.py:2480} INFO - Exporting env vars: AIRFLOW_CTX_DAG_OWNER='Facundo Adrian Lucianna' AIRFLOW_CTX_DAG_ID='process_etl_heart_data' AIRFLOW_CTX_TASK_ID='make_dummies_variables' AIRFLOW_CTX_EXECUTION_DATE='2024-08-12T00:00:00+00:00' AIRFLOW_CTX_TRY_NUMBER='1' AIRFLOW_CTX_DAG_RUN_ID='scheduled__2024-08-12T00:00:00+00:00'
[2024-08-13T23:06:42.213+0000] {process_utils.py:182} INFO - Executing cmd: /usr/local/bin/python -m virtualenv /tmp/venvv5xr58zl --system-site-packages --python=python
[2024-08-13T23:06:42.216+0000] {process_utils.py:186} INFO - Output:
[2024-08-13T23:06:42.462+0000] {process_utils.py:190} INFO - created virtual environment CPython3.8.18.final.0-64 in 77ms
[2024-08-13T23:06:42.462+0000] {process_utils.py:190} INFO -   creator CPython3Posix(dest=/tmp/venvv5xr58zl, clear=False, no_vcs_ignore=False, global=True)
[2024-08-13T23:06:42.463+0000] {process_utils.py:190} INFO -   seeder FromAppData(download=False, pip=bundle, setuptools=bundle, wheel=bundle, via=copy, app_data_dir=/home/***/.local/share/virtualenv)
[2024-08-13T23:06:42.463+0000] {process_utils.py:190} INFO -     added seed packages: pip==23.3.1, setuptools==69.0.2, wheel==0.42.0
[2024-08-13T23:06:42.463+0000] {process_utils.py:190} INFO -   activators BashActivator,CShellActivator,FishActivator,NushellActivator,PowerShellActivator,PythonActivator
[2024-08-13T23:06:42.480+0000] {process_utils.py:182} INFO - Executing cmd: /tmp/venvv5xr58zl/bin/pip install -r /tmp/venvv5xr58zl/requirements.txt
[2024-08-13T23:06:42.482+0000] {process_utils.py:186} INFO - Output:
[2024-08-13T23:06:43.018+0000] {process_utils.py:190} INFO - Collecting awswrangler==3.6.0 (from -r /tmp/venvv5xr58zl/requirements.txt (line 1))
[2024-08-13T23:06:43.019+0000] {process_utils.py:190} INFO -   Using cached awswrangler-3.6.0-py3-none-any.whl.metadata (23 kB)
[2024-08-13T23:06:43.038+0000] {process_utils.py:190} INFO - Requirement already satisfied: boto3<2.0.0,>=1.20.32 in /home/***/.local/lib/python3.8/site-packages (from awswrangler==3.6.0->-r /tmp/venvv5xr58zl/requirements.txt (line 1)) (1.34.158)
[2024-08-13T23:06:43.039+0000] {process_utils.py:190} INFO - Requirement already satisfied: botocore<2.0.0,>=1.23.32 in /home/***/.local/lib/python3.8/site-packages (from awswrangler==3.6.0->-r /tmp/venvv5xr58zl/requirements.txt (line 1)) (1.34.158)
[2024-08-13T23:06:43.039+0000] {process_utils.py:190} INFO - Requirement already satisfied: numpy<2.0,>=1.18 in /home/***/.local/lib/python3.8/site-packages (from awswrangler==3.6.0->-r /tmp/venvv5xr58zl/requirements.txt (line 1)) (1.24.4)
[2024-08-13T23:06:43.040+0000] {process_utils.py:190} INFO - Requirement already satisfied: packaging<24.0,>=21.1 in /home/***/.local/lib/python3.8/site-packages (from awswrangler==3.6.0->-r /tmp/venvv5xr58zl/requirements.txt (line 1)) (23.2)
[2024-08-13T23:06:43.040+0000] {process_utils.py:190} INFO - Requirement already satisfied: pandas<2.1.0,>=1.2.0 in /home/***/.local/lib/python3.8/site-packages (from awswrangler==3.6.0->-r /tmp/venvv5xr58zl/requirements.txt (line 1)) (2.0.3)
[2024-08-13T23:06:43.040+0000] {process_utils.py:190} INFO - Requirement already satisfied: pyarrow>=7.0.0 in /home/***/.local/lib/python3.8/site-packages (from awswrangler==3.6.0->-r /tmp/venvv5xr58zl/requirements.txt (line 1)) (14.0.2)
[2024-08-13T23:06:43.041+0000] {process_utils.py:190} INFO - Requirement already satisfied: typing-extensions<5.0.0,>=4.4.0 in /home/***/.local/lib/python3.8/site-packages (from awswrangler==3.6.0->-r /tmp/venvv5xr58zl/requirements.txt (line 1)) (4.12.2)
[2024-08-13T23:06:43.043+0000] {process_utils.py:190} INFO - Requirement already satisfied: jmespath<2.0.0,>=0.7.1 in /home/***/.local/lib/python3.8/site-packages (from boto3<2.0.0,>=1.20.32->awswrangler==3.6.0->-r /tmp/venvv5xr58zl/requirements.txt (line 1)) (0.10.0)
[2024-08-13T23:06:43.044+0000] {process_utils.py:190} INFO - Requirement already satisfied: s3transfer<0.11.0,>=0.10.0 in /home/***/.local/lib/python3.8/site-packages (from boto3<2.0.0,>=1.20.32->awswrangler==3.6.0->-r /tmp/venvv5xr58zl/requirements.txt (line 1)) (0.10.2)
[2024-08-13T23:06:43.046+0000] {process_utils.py:190} INFO - Requirement already satisfied: python-dateutil<3.0.0,>=2.1 in /home/***/.local/lib/python3.8/site-packages (from botocore<2.0.0,>=1.23.32->awswrangler==3.6.0->-r /tmp/venvv5xr58zl/requirements.txt (line 1)) (2.8.2)
[2024-08-13T23:06:43.047+0000] {process_utils.py:190} INFO - Requirement already satisfied: urllib3<1.27,>=1.25.4 in /home/***/.local/lib/python3.8/site-packages (from botocore<2.0.0,>=1.23.32->awswrangler==3.6.0->-r /tmp/venvv5xr58zl/requirements.txt (line 1)) (1.26.18)
[2024-08-13T23:06:43.082+0000] {process_utils.py:190} INFO - Requirement already satisfied: pytz>=2020.1 in /home/***/.local/lib/python3.8/site-packages (from pandas<2.1.0,>=1.2.0->awswrangler==3.6.0->-r /tmp/venvv5xr58zl/requirements.txt (line 1)) (2023.3.post1)
[2024-08-13T23:06:43.082+0000] {process_utils.py:190} INFO - Requirement already satisfied: tzdata>=2022.1 in /home/***/.local/lib/python3.8/site-packages (from pandas<2.1.0,>=1.2.0->awswrangler==3.6.0->-r /tmp/venvv5xr58zl/requirements.txt (line 1)) (2023.4)
[2024-08-13T23:06:43.086+0000] {process_utils.py:190} INFO - Requirement already satisfied: six>=1.5 in /home/***/.local/lib/python3.8/site-packages (from python-dateutil<3.0.0,>=2.1->botocore<2.0.0,>=1.23.32->awswrangler==3.6.0->-r /tmp/venvv5xr58zl/requirements.txt (line 1)) (1.16.0)
[2024-08-13T23:06:43.099+0000] {process_utils.py:190} INFO - Using cached awswrangler-3.6.0-py3-none-any.whl (403 kB)
[2024-08-13T23:06:44.343+0000] {process_utils.py:190} INFO - Installing collected packages: awswrangler
[2024-08-13T23:06:44.450+0000] {process_utils.py:190} INFO - Successfully installed awswrangler-3.6.0
[2024-08-13T23:06:44.513+0000] {process_utils.py:190} INFO - 
[2024-08-13T23:06:44.514+0000] {process_utils.py:190} INFO - [notice] A new release of pip is available: 23.3.1 -> 24.2
[2024-08-13T23:06:44.514+0000] {process_utils.py:190} INFO - [notice] To update, run: python -m pip install --upgrade pip
[2024-08-13T23:06:44.567+0000] {process_utils.py:182} INFO - Executing cmd: /tmp/venvv5xr58zl/bin/python /tmp/venv-callgwlg4i3y/script.py /tmp/venv-callgwlg4i3y/script.in /tmp/venv-callgwlg4i3y/script.out /tmp/venv-callgwlg4i3y/string_args.txt /tmp/venv-callgwlg4i3y/termination.log
[2024-08-13T23:06:44.569+0000] {process_utils.py:186} INFO - Output:
[2024-08-13T23:06:45.638+0000] {process_utils.py:190} INFO - [[34m2024-08-13T23:06:45.638+0000[0m] {[34mcredentials.py:[0m1147} INFO[0m - Found credentials in environment variables.[0m
[2024-08-13T23:06:45.662+0000] {process_utils.py:190} INFO - [[34m2024-08-13T23:06:45.662+0000[0m] {[34mconfigprovider.py:[0m952} INFO[0m - Found endpoint for s3 via: environment_service.[0m
[2024-08-13T23:06:45.685+0000] {process_utils.py:190} INFO - [[34m2024-08-13T23:06:45.684+0000[0m] {[34mcredentials.py:[0m1147} INFO[0m - Found credentials in environment variables.[0m
[2024-08-13T23:06:45.709+0000] {process_utils.py:190} INFO - [[34m2024-08-13T23:06:45.709+0000[0m] {[34mconfigprovider.py:[0m952} INFO[0m - Found endpoint for s3 via: environment_service.[0m
[2024-08-13T23:06:45.721+0000] {process_utils.py:190} INFO - [[34m2024-08-13T23:06:45.721+0000[0m] {[34mcredentials.py:[0m1147} INFO[0m - Found credentials in environment variables.[0m
[2024-08-13T23:06:45.746+0000] {process_utils.py:190} INFO - [[34m2024-08-13T23:06:45.745+0000[0m] {[34mconfigprovider.py:[0m952} INFO[0m - Found endpoint for s3 via: environment_service.[0m
[2024-08-13T23:06:45.826+0000] {process_utils.py:190} INFO - 2024/08/13 23:06:45 INFO mlflow.tracking.fluent: Experiment with name 'Heart Disease' does not exist. Creating a new experiment.
[2024-08-13T23:06:45.872+0000] {process_utils.py:190} INFO - 2024/08/13 23:06:45 WARNING mlflow.system_metrics.system_metrics_monitor: Skip logging GPU metrics because creating `GPUMonitor` failed with error: `pynvml` is not installed, to log GPU metrics please run `pip install pynvml` to install it..
[2024-08-13T23:06:45.872+0000] {process_utils.py:190} INFO - 2024/08/13 23:06:45 INFO mlflow.system_metrics.system_metrics_monitor: Started monitoring system metrics.
[2024-08-13T23:06:45.887+0000] {process_utils.py:190} INFO - /home/***/.local/lib/python3.8/site-packages/mlflow/data/dataset_source_registry.py:150 UserWarning: Failed to determine whether UCVolumeDatasetSource can resolve source information for 'https://archive.ics.uci.edu/dataset/45/heart+disease'. Exception:
[2024-08-13T23:06:45.891+0000] {process_utils.py:190} INFO - /home/***/.local/lib/python3.8/site-packages/mlflow/data/dataset_source_registry.py:150 UserWarning: Failed to determine whether UCVolumeDatasetSource can resolve source information for 'https://archive.ics.uci.edu/dataset/45/heart+disease'. Exception:
[2024-08-13T23:06:45.895+0000] {process_utils.py:190} INFO - /home/***/.local/lib/python3.8/site-packages/mlflow/types/utils.py:406 UserWarning: Hint: Inferred schema contains integer column(s). Integer columns in Python cannot represent missing values. If your input data contains missing values at inference time, it will be encoded as floats and will cause a schema enforcement error. The best way to avoid this problem is to infer the model schema based on a realistic data sample (training dataset) that includes missing values. Alternatively, you can declare integer columns as doubles (float64) whenever these columns may have missing values. See `Handling Integers With Missing Values <https://www.mlflow.org/docs/latest/models.html#handling-integers-with-missing-values>`_ for more details.
[2024-08-13T23:06:45.919+0000] {process_utils.py:190} INFO - 2024/08/13 23:06:45 INFO mlflow.tracking._tracking_service.client: 🏃 View run ETL_run_2024/08/13-23:06:45" at: http://mlflow:5005/#/experiments/1/runs/d1e50742dc3f4588a5751f2b9188b0dc.
[2024-08-13T23:06:45.919+0000] {process_utils.py:190} INFO - 2024/08/13 23:06:45 INFO mlflow.tracking._tracking_service.client: 🧪 View experiment at: http://mlflow:5005/#/experiments/1.
[2024-08-13T23:06:45.925+0000] {process_utils.py:190} INFO - 2024/08/13 23:06:45 INFO mlflow.system_metrics.system_metrics_monitor: Stopping system metrics monitoring...
[2024-08-13T23:06:45.930+0000] {process_utils.py:190} INFO - 2024/08/13 23:06:45 INFO mlflow.system_metrics.system_metrics_monitor: Successfully terminated system metrics monitoring!
[2024-08-13T23:06:46.150+0000] {python.py:201} INFO - Done. Returned value was: None
[2024-08-13T23:06:46.156+0000] {taskinstance.py:1138} INFO - Marking task as SUCCESS. dag_id=process_etl_heart_data, task_id=make_dummies_variables, execution_date=20240812T000000, start_date=20240813T230642, end_date=20240813T230646
[2024-08-13T23:06:46.174+0000] {local_task_job_runner.py:234} INFO - Task exited with return code 0
[2024-08-13T23:06:46.186+0000] {taskinstance.py:3280} INFO - 1 downstream tasks scheduled from follow-on schedule check
