[2024-08-17T14:03:40.210+0000] {taskinstance.py:1956} INFO - Dependencies all met for dep_context=non-requeueable deps ti=<TaskInstance: process_etl_properties.obtain_original_data manual__2024-08-17T13:58:32.981025+00:00 [queued]>
[2024-08-17T14:03:40.213+0000] {taskinstance.py:1956} INFO - Dependencies all met for dep_context=requeueable deps ti=<TaskInstance: process_etl_properties.obtain_original_data manual__2024-08-17T13:58:32.981025+00:00 [queued]>
[2024-08-17T14:03:40.213+0000] {taskinstance.py:2170} INFO - Starting attempt 2 of 2
[2024-08-17T14:03:40.219+0000] {taskinstance.py:2191} INFO - Executing <Task(_PythonVirtualenvDecoratedOperator): obtain_original_data> on 2024-08-17 13:58:32.981025+00:00
[2024-08-17T14:03:40.221+0000] {standard_task_runner.py:60} INFO - Started process 617 to run task
[2024-08-17T14:03:40.223+0000] {standard_task_runner.py:87} INFO - Running: ['***', 'tasks', 'run', 'process_etl_properties', 'obtain_original_data', 'manual__2024-08-17T13:58:32.981025+00:00', '--job-id', '9', '--raw', '--subdir', 'DAGS_FOLDER/etl_properties_process.py', '--cfg-path', '/tmp/tmpjvsw2ghs']
[2024-08-17T14:03:40.226+0000] {standard_task_runner.py:88} INFO - Job 9: Subtask obtain_original_data
[2024-08-17T14:03:40.248+0000] {task_command.py:423} INFO - Running <TaskInstance: process_etl_properties.obtain_original_data manual__2024-08-17T13:58:32.981025+00:00 [running]> on host 5f2606e33b15
[2024-08-17T14:03:40.283+0000] {taskinstance.py:2480} INFO - Exporting env vars: AIRFLOW_CTX_DAG_OWNER='CEIA TP Final' AIRFLOW_CTX_DAG_ID='process_etl_properties' AIRFLOW_CTX_TASK_ID='obtain_original_data' AIRFLOW_CTX_EXECUTION_DATE='2024-08-17T13:58:32.981025+00:00' AIRFLOW_CTX_TRY_NUMBER='2' AIRFLOW_CTX_DAG_RUN_ID='manual__2024-08-17T13:58:32.981025+00:00'
[2024-08-17T14:03:40.284+0000] {process_utils.py:182} INFO - Executing cmd: /usr/local/bin/python -m virtualenv /tmp/venvnzeza6ys --system-site-packages --python=python
[2024-08-17T14:03:40.287+0000] {process_utils.py:186} INFO - Output:
[2024-08-17T14:03:40.628+0000] {process_utils.py:190} INFO - created virtual environment CPython3.8.18.final.0-64 in 165ms
[2024-08-17T14:03:40.629+0000] {process_utils.py:190} INFO -   creator CPython3Posix(dest=/tmp/venvnzeza6ys, clear=False, no_vcs_ignore=False, global=True)
[2024-08-17T14:03:40.629+0000] {process_utils.py:190} INFO -   seeder FromAppData(download=False, pip=bundle, setuptools=bundle, wheel=bundle, via=copy, app_data_dir=/tmp/tmpdnv3jv64)
[2024-08-17T14:03:40.629+0000] {process_utils.py:190} INFO -     added seed packages: pip==23.3.1, setuptools==69.0.2, wheel==0.42.0
[2024-08-17T14:03:40.629+0000] {process_utils.py:190} INFO -   activators BashActivator,CShellActivator,FishActivator,NushellActivator,PowerShellActivator,PythonActivator
[2024-08-17T14:03:40.646+0000] {process_utils.py:182} INFO - Executing cmd: /tmp/venvnzeza6ys/bin/pip install -r /tmp/venvnzeza6ys/requirements.txt
[2024-08-17T14:03:40.650+0000] {process_utils.py:186} INFO - Output:
[2024-08-17T14:03:41.066+0000] {process_utils.py:190} INFO - WARNING: The directory '/home/***/.cache/pip' or its parent directory is not owned or is not writable by the current user. The cache has been disabled. Check the permissions and owner of that directory. If executing pip with sudo, you should use sudo's -H flag.
[2024-08-17T14:03:41.238+0000] {process_utils.py:190} INFO - Collecting awswrangler==3.6.0 (from -r /tmp/venvnzeza6ys/requirements.txt (line 1))
[2024-08-17T14:03:41.386+0000] {process_utils.py:190} INFO -   Downloading awswrangler-3.6.0-py3-none-any.whl.metadata (23 kB)
[2024-08-17T14:03:41.391+0000] {process_utils.py:190} INFO - Requirement already satisfied: pandas in /home/***/.local/lib/python3.8/site-packages (from -r /tmp/venvnzeza6ys/requirements.txt (line 2)) (2.0.3)
[2024-08-17T14:03:41.408+0000] {process_utils.py:190} INFO - Collecting ucimlrepo==0.0.3 (from -r /tmp/venvnzeza6ys/requirements.txt (line 3))
[2024-08-17T14:03:41.440+0000] {process_utils.py:190} INFO -   Downloading ucimlrepo-0.0.3-py3-none-any.whl.metadata (5.2 kB)
[2024-08-17T14:03:41.463+0000] {process_utils.py:190} INFO - Requirement already satisfied: boto3<2.0.0,>=1.20.32 in /home/***/.local/lib/python3.8/site-packages (from awswrangler==3.6.0->-r /tmp/venvnzeza6ys/requirements.txt (line 1)) (1.34.158)
[2024-08-17T14:03:41.464+0000] {process_utils.py:190} INFO - Requirement already satisfied: botocore<2.0.0,>=1.23.32 in /home/***/.local/lib/python3.8/site-packages (from awswrangler==3.6.0->-r /tmp/venvnzeza6ys/requirements.txt (line 1)) (1.34.158)
[2024-08-17T14:03:41.465+0000] {process_utils.py:190} INFO - Requirement already satisfied: numpy<2.0,>=1.18 in /home/***/.local/lib/python3.8/site-packages (from awswrangler==3.6.0->-r /tmp/venvnzeza6ys/requirements.txt (line 1)) (1.24.4)
[2024-08-17T14:03:41.465+0000] {process_utils.py:190} INFO - Requirement already satisfied: packaging<24.0,>=21.1 in /home/***/.local/lib/python3.8/site-packages (from awswrangler==3.6.0->-r /tmp/venvnzeza6ys/requirements.txt (line 1)) (23.2)
[2024-08-17T14:03:41.466+0000] {process_utils.py:190} INFO - Requirement already satisfied: pyarrow>=7.0.0 in /home/***/.local/lib/python3.8/site-packages (from awswrangler==3.6.0->-r /tmp/venvnzeza6ys/requirements.txt (line 1)) (14.0.2)
[2024-08-17T14:03:41.466+0000] {process_utils.py:190} INFO - Requirement already satisfied: typing-extensions<5.0.0,>=4.4.0 in /home/***/.local/lib/python3.8/site-packages (from awswrangler==3.6.0->-r /tmp/venvnzeza6ys/requirements.txt (line 1)) (4.12.2)
[2024-08-17T14:03:41.503+0000] {process_utils.py:190} INFO - Requirement already satisfied: python-dateutil>=2.8.2 in /home/***/.local/lib/python3.8/site-packages (from pandas->-r /tmp/venvnzeza6ys/requirements.txt (line 2)) (2.8.2)
[2024-08-17T14:03:41.504+0000] {process_utils.py:190} INFO - Requirement already satisfied: pytz>=2020.1 in /home/***/.local/lib/python3.8/site-packages (from pandas->-r /tmp/venvnzeza6ys/requirements.txt (line 2)) (2023.3.post1)
[2024-08-17T14:03:41.504+0000] {process_utils.py:190} INFO - Requirement already satisfied: tzdata>=2022.1 in /home/***/.local/lib/python3.8/site-packages (from pandas->-r /tmp/venvnzeza6ys/requirements.txt (line 2)) (2023.4)
[2024-08-17T14:03:41.506+0000] {process_utils.py:190} INFO - Requirement already satisfied: jmespath<2.0.0,>=0.7.1 in /home/***/.local/lib/python3.8/site-packages (from boto3<2.0.0,>=1.20.32->awswrangler==3.6.0->-r /tmp/venvnzeza6ys/requirements.txt (line 1)) (0.10.0)
[2024-08-17T14:03:41.507+0000] {process_utils.py:190} INFO - Requirement already satisfied: s3transfer<0.11.0,>=0.10.0 in /home/***/.local/lib/python3.8/site-packages (from boto3<2.0.0,>=1.20.32->awswrangler==3.6.0->-r /tmp/venvnzeza6ys/requirements.txt (line 1)) (0.10.2)
[2024-08-17T14:03:41.510+0000] {process_utils.py:190} INFO - Requirement already satisfied: urllib3<1.27,>=1.25.4 in /home/***/.local/lib/python3.8/site-packages (from botocore<2.0.0,>=1.23.32->awswrangler==3.6.0->-r /tmp/venvnzeza6ys/requirements.txt (line 1)) (1.26.18)
[2024-08-17T14:03:41.513+0000] {process_utils.py:190} INFO - Requirement already satisfied: six>=1.5 in /home/***/.local/lib/python3.8/site-packages (from python-dateutil>=2.8.2->pandas->-r /tmp/venvnzeza6ys/requirements.txt (line 2)) (1.16.0)
[2024-08-17T14:03:41.562+0000] {process_utils.py:190} INFO - Downloading awswrangler-3.6.0-py3-none-any.whl (403 kB)
[2024-08-17T14:03:41.721+0000] {process_utils.py:190} INFO -    ━━━━━━━━━━━━━━━━━━━━━━━━━━━━━━━━━━━━━━━━ 403.8/403.8 kB 2.6 MB/s eta 0:00:00
[2024-08-17T14:03:41.753+0000] {process_utils.py:190} INFO - Downloading ucimlrepo-0.0.3-py3-none-any.whl (7.0 kB)
[2024-08-17T14:03:42.988+0000] {process_utils.py:190} INFO - Installing collected packages: ucimlrepo, awswrangler
[2024-08-17T14:03:43.105+0000] {process_utils.py:190} INFO - Successfully installed awswrangler-3.6.0 ucimlrepo-0.0.3
[2024-08-17T14:03:43.186+0000] {process_utils.py:190} INFO - 
[2024-08-17T14:03:43.186+0000] {process_utils.py:190} INFO - [notice] A new release of pip is available: 23.3.1 -> 24.2
[2024-08-17T14:03:43.186+0000] {process_utils.py:190} INFO - [notice] To update, run: python -m pip install --upgrade pip
[2024-08-17T14:03:43.254+0000] {process_utils.py:182} INFO - Executing cmd: /tmp/venvnzeza6ys/bin/python /tmp/venv-calld5cawrlv/script.py /tmp/venv-calld5cawrlv/script.in /tmp/venv-calld5cawrlv/script.out /tmp/venv-calld5cawrlv/string_args.txt /tmp/venv-calld5cawrlv/termination.log
[2024-08-17T14:03:43.257+0000] {process_utils.py:186} INFO - Output:
[2024-08-17T14:03:45.310+0000] {process_utils.py:190} INFO - Traceback (most recent call last):
[2024-08-17T14:03:45.311+0000] {process_utils.py:190} INFO -   File "/tmp/venv-calld5cawrlv/script.py", line 46, in <module>
[2024-08-17T14:03:45.311+0000] {process_utils.py:190} INFO -     res = get_data(*arg_dict["args"], **arg_dict["kwargs"])
[2024-08-17T14:03:45.311+0000] {process_utils.py:190} INFO -   File "/tmp/venv-calld5cawrlv/script.py", line 37, in get_data
[2024-08-17T14:03:45.312+0000] {process_utils.py:190} INFO -     origin = pd.read_csv(URL_DATASET)
[2024-08-17T14:03:45.312+0000] {process_utils.py:190} INFO -   File "/home/***/.local/lib/python3.8/site-packages/pandas/io/parsers/readers.py", line 912, in read_csv
[2024-08-17T14:03:45.312+0000] {process_utils.py:190} INFO -     return _read(filepath_or_buffer, kwds)
[2024-08-17T14:03:45.312+0000] {process_utils.py:190} INFO -   File "/home/***/.local/lib/python3.8/site-packages/pandas/io/parsers/readers.py", line 583, in _read
[2024-08-17T14:03:45.313+0000] {process_utils.py:190} INFO -     return parser.read(nrows)
[2024-08-17T14:03:45.313+0000] {process_utils.py:190} INFO -   File "/home/***/.local/lib/python3.8/site-packages/pandas/io/parsers/readers.py", line 1704, in read
[2024-08-17T14:03:45.313+0000] {process_utils.py:190} INFO -     ) = self._engine.read(  # type: ignore[attr-defined]
[2024-08-17T14:03:45.314+0000] {process_utils.py:190} INFO -   File "/home/***/.local/lib/python3.8/site-packages/pandas/io/parsers/c_parser_wrapper.py", line 234, in read
[2024-08-17T14:03:45.314+0000] {process_utils.py:190} INFO -     chunks = self._reader.read_low_memory(nrows)
[2024-08-17T14:03:45.314+0000] {process_utils.py:190} INFO -   File "pandas/_libs/parsers.pyx", line 814, in pandas._libs.parsers.TextReader.read_low_memory
[2024-08-17T14:03:45.314+0000] {process_utils.py:190} INFO -   File "pandas/_libs/parsers.pyx", line 875, in pandas._libs.parsers.TextReader._read_rows
[2024-08-17T14:03:45.315+0000] {process_utils.py:190} INFO -   File "pandas/_libs/parsers.pyx", line 850, in pandas._libs.parsers.TextReader._tokenize_rows
[2024-08-17T14:03:45.315+0000] {process_utils.py:190} INFO -   File "pandas/_libs/parsers.pyx", line 861, in pandas._libs.parsers.TextReader._check_tokenize_status
[2024-08-17T14:03:45.315+0000] {process_utils.py:190} INFO -   File "pandas/_libs/parsers.pyx", line 2029, in pandas._libs.parsers.raise_parser_error
[2024-08-17T14:03:45.315+0000] {process_utils.py:190} INFO - pandas.errors.ParserError: Error tokenizing data. C error: Expected 353 fields in line 7, saw 3648
[2024-08-17T14:03:45.316+0000] {process_utils.py:190} INFO - 
[2024-08-17T14:03:45.448+0000] {taskinstance.py:2698} ERROR - Task failed with exception
Traceback (most recent call last):
  File "/home/airflow/.local/lib/python3.8/site-packages/airflow/models/taskinstance.py", line 433, in _execute_task
    result = execute_callable(context=context, **execute_callable_kwargs)
  File "/home/airflow/.local/lib/python3.8/site-packages/airflow/decorators/base.py", line 241, in execute
    return_value = super().execute(context)
  File "/home/airflow/.local/lib/python3.8/site-packages/airflow/operators/python.py", line 400, in execute
    return super().execute(context=serializable_context)
  File "/home/airflow/.local/lib/python3.8/site-packages/airflow/operators/python.py", line 199, in execute
    return_value = self.execute_callable()
  File "/home/airflow/.local/lib/python3.8/site-packages/airflow/operators/python.py", line 716, in execute_callable
    result = self._execute_python_callable_in_subprocess(python_path)
  File "/home/airflow/.local/lib/python3.8/site-packages/airflow/operators/python.py", line 471, in _execute_python_callable_in_subprocess
    raise AirflowException(error_msg) from None
airflow.exceptions.AirflowException: Process returned non-zero exit status 1.
Error tokenizing data. C error: Expected 353 fields in line 7, saw 3648

[2024-08-17T14:03:45.450+0000] {taskinstance.py:1138} INFO - Marking task as FAILED. dag_id=process_etl_properties, task_id=obtain_original_data, execution_date=20240817T135832, start_date=20240817T140340, end_date=20240817T140345
[2024-08-17T14:03:45.456+0000] {standard_task_runner.py:107} ERROR - Failed to execute job 9 for task obtain_original_data (Process returned non-zero exit status 1.
Error tokenizing data. C error: Expected 353 fields in line 7, saw 3648
; 617)
[2024-08-17T14:03:45.473+0000] {local_task_job_runner.py:234} INFO - Task exited with return code 1
[2024-08-17T14:03:45.481+0000] {taskinstance.py:3280} INFO - 0 downstream tasks scheduled from follow-on schedule check
