[2024-08-13T02:06:06.176+0000] {taskinstance.py:1956} INFO - Dependencies all met for dep_context=non-requeueable deps ti=<TaskInstance: process_etl_heart_data.make_dummies_variables manual__2024-08-13T02:05:59.218737+00:00 [queued]>
[2024-08-13T02:06:06.179+0000] {taskinstance.py:1956} INFO - Dependencies all met for dep_context=requeueable deps ti=<TaskInstance: process_etl_heart_data.make_dummies_variables manual__2024-08-13T02:05:59.218737+00:00 [queued]>
[2024-08-13T02:06:06.179+0000] {taskinstance.py:2170} INFO - Starting attempt 1 of 2
[2024-08-13T02:06:06.184+0000] {taskinstance.py:2191} INFO - Executing <Task(_PythonVirtualenvDecoratedOperator): make_dummies_variables> on 2024-08-13 02:05:59.218737+00:00
[2024-08-13T02:06:06.186+0000] {standard_task_runner.py:60} INFO - Started process 1988 to run task
[2024-08-13T02:06:06.187+0000] {standard_task_runner.py:87} INFO - Running: ['***', 'tasks', 'run', 'process_etl_heart_data', 'make_dummies_variables', 'manual__2024-08-13T02:05:59.218737+00:00', '--job-id', '13', '--raw', '--subdir', 'DAGS_FOLDER/etl_process.py', '--cfg-path', '/tmp/tmpm5dywiwk']
[2024-08-13T02:06:06.188+0000] {standard_task_runner.py:88} INFO - Job 13: Subtask make_dummies_variables
[2024-08-13T02:06:06.207+0000] {task_command.py:423} INFO - Running <TaskInstance: process_etl_heart_data.make_dummies_variables manual__2024-08-13T02:05:59.218737+00:00 [running]> on host 9c98cbfa0d20
[2024-08-13T02:06:06.234+0000] {taskinstance.py:2480} INFO - Exporting env vars: AIRFLOW_CTX_DAG_OWNER='Facundo Adrian Lucianna' AIRFLOW_CTX_DAG_ID='process_etl_heart_data' AIRFLOW_CTX_TASK_ID='make_dummies_variables' AIRFLOW_CTX_EXECUTION_DATE='2024-08-13T02:05:59.218737+00:00' AIRFLOW_CTX_TRY_NUMBER='1' AIRFLOW_CTX_DAG_RUN_ID='manual__2024-08-13T02:05:59.218737+00:00'
[2024-08-13T02:06:06.235+0000] {process_utils.py:182} INFO - Executing cmd: /usr/local/bin/python -m virtualenv /tmp/venvrcoh8v05 --system-site-packages --python=python
[2024-08-13T02:06:06.238+0000] {process_utils.py:186} INFO - Output:
[2024-08-13T02:06:06.532+0000] {process_utils.py:190} INFO - created virtual environment CPython3.8.18.final.0-64 in 132ms
[2024-08-13T02:06:06.532+0000] {process_utils.py:190} INFO -   creator CPython3Posix(dest=/tmp/venvrcoh8v05, clear=False, no_vcs_ignore=False, global=True)
[2024-08-13T02:06:06.532+0000] {process_utils.py:190} INFO -   seeder FromAppData(download=False, pip=bundle, setuptools=bundle, wheel=bundle, via=copy, app_data_dir=/tmp/tmpzqtcewa8)
[2024-08-13T02:06:06.533+0000] {process_utils.py:190} INFO -     added seed packages: pip==23.3.1, setuptools==69.0.2, wheel==0.42.0
[2024-08-13T02:06:06.533+0000] {process_utils.py:190} INFO -   activators BashActivator,CShellActivator,FishActivator,NushellActivator,PowerShellActivator,PythonActivator
[2024-08-13T02:06:06.548+0000] {process_utils.py:182} INFO - Executing cmd: /tmp/venvrcoh8v05/bin/pip install -r /tmp/venvrcoh8v05/requirements.txt
[2024-08-13T02:06:06.551+0000] {process_utils.py:186} INFO - Output:
[2024-08-13T02:06:06.930+0000] {process_utils.py:190} INFO - WARNING: The directory '/home/***/.cache/pip' or its parent directory is not owned or is not writable by the current user. The cache has been disabled. Check the permissions and owner of that directory. If executing pip with sudo, you should use sudo's -H flag.
[2024-08-13T02:06:07.073+0000] {process_utils.py:190} INFO - Collecting awswrangler==3.6.0 (from -r /tmp/venvrcoh8v05/requirements.txt (line 1))
[2024-08-13T02:06:07.113+0000] {process_utils.py:190} INFO -   Downloading awswrangler-3.6.0-py3-none-any.whl.metadata (23 kB)
[2024-08-13T02:06:07.133+0000] {process_utils.py:190} INFO - Requirement already satisfied: boto3<2.0.0,>=1.20.32 in /home/***/.local/lib/python3.8/site-packages (from awswrangler==3.6.0->-r /tmp/venvrcoh8v05/requirements.txt (line 1)) (1.34.158)
[2024-08-13T02:06:07.134+0000] {process_utils.py:190} INFO - Requirement already satisfied: botocore<2.0.0,>=1.23.32 in /home/***/.local/lib/python3.8/site-packages (from awswrangler==3.6.0->-r /tmp/venvrcoh8v05/requirements.txt (line 1)) (1.34.158)
[2024-08-13T02:06:07.134+0000] {process_utils.py:190} INFO - Requirement already satisfied: numpy<2.0,>=1.18 in /home/***/.local/lib/python3.8/site-packages (from awswrangler==3.6.0->-r /tmp/venvrcoh8v05/requirements.txt (line 1)) (1.24.4)
[2024-08-13T02:06:07.135+0000] {process_utils.py:190} INFO - Requirement already satisfied: packaging<24.0,>=21.1 in /home/***/.local/lib/python3.8/site-packages (from awswrangler==3.6.0->-r /tmp/venvrcoh8v05/requirements.txt (line 1)) (23.2)
[2024-08-13T02:06:07.135+0000] {process_utils.py:190} INFO - Requirement already satisfied: pandas<2.1.0,>=1.2.0 in /home/***/.local/lib/python3.8/site-packages (from awswrangler==3.6.0->-r /tmp/venvrcoh8v05/requirements.txt (line 1)) (2.0.3)
[2024-08-13T02:06:07.135+0000] {process_utils.py:190} INFO - Requirement already satisfied: pyarrow>=7.0.0 in /home/***/.local/lib/python3.8/site-packages (from awswrangler==3.6.0->-r /tmp/venvrcoh8v05/requirements.txt (line 1)) (14.0.2)
[2024-08-13T02:06:07.136+0000] {process_utils.py:190} INFO - Requirement already satisfied: typing-extensions<5.0.0,>=4.4.0 in /home/***/.local/lib/python3.8/site-packages (from awswrangler==3.6.0->-r /tmp/venvrcoh8v05/requirements.txt (line 1)) (4.12.2)
[2024-08-13T02:06:07.138+0000] {process_utils.py:190} INFO - Requirement already satisfied: jmespath<2.0.0,>=0.7.1 in /home/***/.local/lib/python3.8/site-packages (from boto3<2.0.0,>=1.20.32->awswrangler==3.6.0->-r /tmp/venvrcoh8v05/requirements.txt (line 1)) (0.10.0)
[2024-08-13T02:06:07.138+0000] {process_utils.py:190} INFO - Requirement already satisfied: s3transfer<0.11.0,>=0.10.0 in /home/***/.local/lib/python3.8/site-packages (from boto3<2.0.0,>=1.20.32->awswrangler==3.6.0->-r /tmp/venvrcoh8v05/requirements.txt (line 1)) (0.10.2)
[2024-08-13T02:06:07.141+0000] {process_utils.py:190} INFO - Requirement already satisfied: python-dateutil<3.0.0,>=2.1 in /home/***/.local/lib/python3.8/site-packages (from botocore<2.0.0,>=1.23.32->awswrangler==3.6.0->-r /tmp/venvrcoh8v05/requirements.txt (line 1)) (2.8.2)
[2024-08-13T02:06:07.142+0000] {process_utils.py:190} INFO - Requirement already satisfied: urllib3<1.27,>=1.25.4 in /home/***/.local/lib/python3.8/site-packages (from botocore<2.0.0,>=1.23.32->awswrangler==3.6.0->-r /tmp/venvrcoh8v05/requirements.txt (line 1)) (1.26.18)
[2024-08-13T02:06:07.176+0000] {process_utils.py:190} INFO - Requirement already satisfied: pytz>=2020.1 in /home/***/.local/lib/python3.8/site-packages (from pandas<2.1.0,>=1.2.0->awswrangler==3.6.0->-r /tmp/venvrcoh8v05/requirements.txt (line 1)) (2023.3.post1)
[2024-08-13T02:06:07.177+0000] {process_utils.py:190} INFO - Requirement already satisfied: tzdata>=2022.1 in /home/***/.local/lib/python3.8/site-packages (from pandas<2.1.0,>=1.2.0->awswrangler==3.6.0->-r /tmp/venvrcoh8v05/requirements.txt (line 1)) (2023.4)
[2024-08-13T02:06:07.180+0000] {process_utils.py:190} INFO - Requirement already satisfied: six>=1.5 in /home/***/.local/lib/python3.8/site-packages (from python-dateutil<3.0.0,>=2.1->botocore<2.0.0,>=1.23.32->awswrangler==3.6.0->-r /tmp/venvrcoh8v05/requirements.txt (line 1)) (1.16.0)
[2024-08-13T02:06:07.201+0000] {process_utils.py:190} INFO - Downloading awswrangler-3.6.0-py3-none-any.whl (403 kB)
[2024-08-13T02:06:07.227+0000] {process_utils.py:190} INFO -    ━━━━━━━━━━━━━━━━━━━━━━━━━━━━━━━━━━━━━━━━ 403.8/403.8 kB 16.1 MB/s eta 0:00:00
[2024-08-13T02:06:08.384+0000] {process_utils.py:190} INFO - Installing collected packages: awswrangler
[2024-08-13T02:06:08.485+0000] {process_utils.py:190} INFO - Successfully installed awswrangler-3.6.0
[2024-08-13T02:06:08.550+0000] {process_utils.py:190} INFO - 
[2024-08-13T02:06:08.551+0000] {process_utils.py:190} INFO - [notice] A new release of pip is available: 23.3.1 -> 24.2
[2024-08-13T02:06:08.551+0000] {process_utils.py:190} INFO - [notice] To update, run: python -m pip install --upgrade pip
[2024-08-13T02:06:08.627+0000] {process_utils.py:182} INFO - Executing cmd: /tmp/venvrcoh8v05/bin/python /tmp/venv-calld3mc8wat/script.py /tmp/venv-calld3mc8wat/script.in /tmp/venv-calld3mc8wat/script.out /tmp/venv-calld3mc8wat/string_args.txt /tmp/venv-calld3mc8wat/termination.log
[2024-08-13T02:06:08.630+0000] {process_utils.py:186} INFO - Output:
[2024-08-13T02:06:09.584+0000] {process_utils.py:190} INFO - [[34m2024-08-13T02:06:09.584+0000[0m] {[34mcredentials.py:[0m1147} INFO[0m - Found credentials in environment variables.[0m
[2024-08-13T02:06:09.609+0000] {process_utils.py:190} INFO - [[34m2024-08-13T02:06:09.609+0000[0m] {[34mconfigprovider.py:[0m952} INFO[0m - Found endpoint for s3 via: environment_service.[0m
[2024-08-13T02:06:09.630+0000] {process_utils.py:190} INFO - [[34m2024-08-13T02:06:09.629+0000[0m] {[34mcredentials.py:[0m1147} INFO[0m - Found credentials in environment variables.[0m
[2024-08-13T02:06:09.653+0000] {process_utils.py:190} INFO - [[34m2024-08-13T02:06:09.653+0000[0m] {[34mconfigprovider.py:[0m952} INFO[0m - Found endpoint for s3 via: environment_service.[0m
[2024-08-13T02:06:09.666+0000] {process_utils.py:190} INFO - [[34m2024-08-13T02:06:09.665+0000[0m] {[34mcredentials.py:[0m1147} INFO[0m - Found credentials in environment variables.[0m
[2024-08-13T02:06:09.689+0000] {process_utils.py:190} INFO - [[34m2024-08-13T02:06:09.689+0000[0m] {[34mconfigprovider.py:[0m952} INFO[0m - Found endpoint for s3 via: environment_service.[0m
[2024-08-13T02:06:09.754+0000] {process_utils.py:190} INFO - [[34m2024-08-13T02:06:09.754+0000[0m] {[34mconnectionpool.py:[0m824} WARNING[0m - Retrying (JitteredRetry(total=4, connect=4, read=5, redirect=5, status=5)) after connection broken by 'NewConnectionError('<urllib3.connection.HTTPConnection object at 0xffff40146d90>: Failed to establish a new connection: [Errno 111] Connection refused')': /api/2.0/mlflow/experiments/get-by-name?experiment_name=Heart+Disease[0m
[2024-08-13T02:06:13.761+0000] {process_utils.py:190} INFO - [[34m2024-08-13T02:06:13.760+0000[0m] {[34mconnectionpool.py:[0m824} WARNING[0m - Retrying (JitteredRetry(total=3, connect=3, read=5, redirect=5, status=5)) after connection broken by 'NewConnectionError('<urllib3.connection.HTTPConnection object at 0xffff3daa8bb0>: Failed to establish a new connection: [Errno 111] Connection refused')': /api/2.0/mlflow/experiments/get-by-name?experiment_name=Heart+Disease[0m
[2024-08-13T02:06:21.773+0000] {process_utils.py:190} INFO - [[34m2024-08-13T02:06:21.771+0000[0m] {[34mconnectionpool.py:[0m824} WARNING[0m - Retrying (JitteredRetry(total=2, connect=2, read=5, redirect=5, status=5)) after connection broken by 'NewConnectionError('<urllib3.connection.HTTPConnection object at 0xffff3daa8a60>: Failed to establish a new connection: [Errno 111] Connection refused')': /api/2.0/mlflow/experiments/get-by-name?experiment_name=Heart+Disease[0m
[2024-08-13T02:06:37.798+0000] {process_utils.py:190} INFO - [[34m2024-08-13T02:06:37.797+0000[0m] {[34mconnectionpool.py:[0m824} WARNING[0m - Retrying (JitteredRetry(total=1, connect=1, read=5, redirect=5, status=5)) after connection broken by 'NewConnectionError('<urllib3.connection.HTTPConnection object at 0xffff3daa8e80>: Failed to establish a new connection: [Errno 111] Connection refused')': /api/2.0/mlflow/experiments/get-by-name?experiment_name=Heart+Disease[0m
[2024-08-13T02:07:09.841+0000] {process_utils.py:190} INFO - [[34m2024-08-13T02:07:09.839+0000[0m] {[34mconnectionpool.py:[0m824} WARNING[0m - Retrying (JitteredRetry(total=0, connect=0, read=5, redirect=5, status=5)) after connection broken by 'NewConnectionError('<urllib3.connection.HTTPConnection object at 0xffff3db18be0>: Failed to establish a new connection: [Errno 111] Connection refused')': /api/2.0/mlflow/experiments/get-by-name?experiment_name=Heart+Disease[0m
[2024-08-13T02:07:09.848+0000] {process_utils.py:190} INFO - Traceback (most recent call last):
[2024-08-13T02:07:09.849+0000] {process_utils.py:190} INFO -   File "/home/***/.local/lib/python3.8/site-packages/urllib3/connection.py", line 174, in _new_conn
[2024-08-13T02:07:09.850+0000] {process_utils.py:190} INFO -     conn = connection.create_connection(
[2024-08-13T02:07:09.852+0000] {process_utils.py:190} INFO -   File "/home/***/.local/lib/python3.8/site-packages/urllib3/util/connection.py", line 95, in create_connection
[2024-08-13T02:07:09.853+0000] {process_utils.py:190} INFO -     raise err
[2024-08-13T02:07:09.853+0000] {process_utils.py:190} INFO -   File "/home/***/.local/lib/python3.8/site-packages/urllib3/util/connection.py", line 85, in create_connection
[2024-08-13T02:07:09.853+0000] {process_utils.py:190} INFO -     sock.connect(sa)
[2024-08-13T02:07:09.854+0000] {process_utils.py:190} INFO - ConnectionRefusedError: [Errno 111] Connection refused
[2024-08-13T02:07:09.855+0000] {process_utils.py:190} INFO - 
[2024-08-13T02:07:09.856+0000] {process_utils.py:190} INFO - During handling of the above exception, another exception occurred:
[2024-08-13T02:07:09.856+0000] {process_utils.py:190} INFO - 
[2024-08-13T02:07:09.856+0000] {process_utils.py:190} INFO - Traceback (most recent call last):
[2024-08-13T02:07:09.856+0000] {process_utils.py:190} INFO -   File "/home/***/.local/lib/python3.8/site-packages/urllib3/connectionpool.py", line 715, in urlopen
[2024-08-13T02:07:09.857+0000] {process_utils.py:190} INFO -     httplib_response = self._make_request(
[2024-08-13T02:07:09.857+0000] {process_utils.py:190} INFO -   File "/home/***/.local/lib/python3.8/site-packages/urllib3/connectionpool.py", line 416, in _make_request
[2024-08-13T02:07:09.857+0000] {process_utils.py:190} INFO -     conn.request(method, url, **httplib_request_kw)
[2024-08-13T02:07:09.858+0000] {process_utils.py:190} INFO -   File "/home/***/.local/lib/python3.8/site-packages/urllib3/connection.py", line 244, in request
[2024-08-13T02:07:09.858+0000] {process_utils.py:190} INFO -     super(HTTPConnection, self).request(method, url, body=body, headers=headers)
[2024-08-13T02:07:09.858+0000] {process_utils.py:190} INFO -   File "/usr/local/lib/python3.8/http/client.py", line 1256, in request
[2024-08-13T02:07:09.859+0000] {process_utils.py:190} INFO -     self._send_request(method, url, body, headers, encode_chunked)
[2024-08-13T02:07:09.859+0000] {process_utils.py:190} INFO -   File "/usr/local/lib/python3.8/http/client.py", line 1302, in _send_request
[2024-08-13T02:07:09.859+0000] {process_utils.py:190} INFO -     self.endheaders(body, encode_chunked=encode_chunked)
[2024-08-13T02:07:09.859+0000] {process_utils.py:190} INFO -   File "/usr/local/lib/python3.8/http/client.py", line 1251, in endheaders
[2024-08-13T02:07:09.860+0000] {process_utils.py:190} INFO -     self._send_output(message_body, encode_chunked=encode_chunked)
[2024-08-13T02:07:09.860+0000] {process_utils.py:190} INFO -   File "/usr/local/lib/python3.8/http/client.py", line 1011, in _send_output
[2024-08-13T02:07:09.860+0000] {process_utils.py:190} INFO -     self.send(msg)
[2024-08-13T02:07:09.861+0000] {process_utils.py:190} INFO -   File "/usr/local/lib/python3.8/http/client.py", line 951, in send
[2024-08-13T02:07:09.861+0000] {process_utils.py:190} INFO -     self.connect()
[2024-08-13T02:07:09.861+0000] {process_utils.py:190} INFO -   File "/home/***/.local/lib/python3.8/site-packages/urllib3/connection.py", line 205, in connect
[2024-08-13T02:07:09.861+0000] {process_utils.py:190} INFO -     conn = self._new_conn()
[2024-08-13T02:07:09.862+0000] {process_utils.py:190} INFO -   File "/home/***/.local/lib/python3.8/site-packages/urllib3/connection.py", line 186, in _new_conn
[2024-08-13T02:07:09.862+0000] {process_utils.py:190} INFO -     raise NewConnectionError(
[2024-08-13T02:07:09.863+0000] {process_utils.py:190} INFO - urllib3.exceptions.NewConnectionError: <urllib3.connection.HTTPConnection object at 0xffff3db188e0>: Failed to establish a new connection: [Errno 111] Connection refused
[2024-08-13T02:07:09.863+0000] {process_utils.py:190} INFO - 
[2024-08-13T02:07:09.864+0000] {process_utils.py:190} INFO - During handling of the above exception, another exception occurred:
[2024-08-13T02:07:09.864+0000] {process_utils.py:190} INFO - 
[2024-08-13T02:07:09.864+0000] {process_utils.py:190} INFO - Traceback (most recent call last):
[2024-08-13T02:07:09.865+0000] {process_utils.py:190} INFO -   File "/home/***/.local/lib/python3.8/site-packages/requests/adapters.py", line 486, in send
[2024-08-13T02:07:09.865+0000] {process_utils.py:190} INFO -     resp = conn.urlopen(
[2024-08-13T02:07:09.865+0000] {process_utils.py:190} INFO -   File "/home/***/.local/lib/python3.8/site-packages/urllib3/connectionpool.py", line 827, in urlopen
[2024-08-13T02:07:09.865+0000] {process_utils.py:190} INFO -     return self.urlopen(
[2024-08-13T02:07:09.866+0000] {process_utils.py:190} INFO -   File "/home/***/.local/lib/python3.8/site-packages/urllib3/connectionpool.py", line 827, in urlopen
[2024-08-13T02:07:09.866+0000] {process_utils.py:190} INFO -     return self.urlopen(
[2024-08-13T02:07:09.866+0000] {process_utils.py:190} INFO -   File "/home/***/.local/lib/python3.8/site-packages/urllib3/connectionpool.py", line 827, in urlopen
[2024-08-13T02:07:09.866+0000] {process_utils.py:190} INFO -     return self.urlopen(
[2024-08-13T02:07:09.867+0000] {process_utils.py:190} INFO -   [Previous line repeated 2 more times]
[2024-08-13T02:07:09.867+0000] {process_utils.py:190} INFO -   File "/home/***/.local/lib/python3.8/site-packages/urllib3/connectionpool.py", line 799, in urlopen
[2024-08-13T02:07:09.867+0000] {process_utils.py:190} INFO -     retries = retries.increment(
[2024-08-13T02:07:09.867+0000] {process_utils.py:190} INFO -   File "/home/***/.local/lib/python3.8/site-packages/urllib3/util/retry.py", line 592, in increment
[2024-08-13T02:07:09.868+0000] {process_utils.py:190} INFO -     raise MaxRetryError(_pool, url, error or ResponseError(cause))
[2024-08-13T02:07:09.868+0000] {process_utils.py:190} INFO - urllib3.exceptions.MaxRetryError: HTTPConnectionPool(host='mlflow', port=5005): Max retries exceeded with url: /api/2.0/mlflow/experiments/get-by-name?experiment_name=Heart+Disease (Caused by NewConnectionError('<urllib3.connection.HTTPConnection object at 0xffff3db188e0>: Failed to establish a new connection: [Errno 111] Connection refused'))
[2024-08-13T02:07:09.869+0000] {process_utils.py:190} INFO - 
[2024-08-13T02:07:09.869+0000] {process_utils.py:190} INFO - During handling of the above exception, another exception occurred:
[2024-08-13T02:07:09.869+0000] {process_utils.py:190} INFO - 
[2024-08-13T02:07:09.869+0000] {process_utils.py:190} INFO - Traceback (most recent call last):
[2024-08-13T02:07:09.870+0000] {process_utils.py:190} INFO -   File "/home/***/.local/lib/python3.8/site-packages/mlflow/utils/rest_utils.py", line 187, in http_request
[2024-08-13T02:07:09.870+0000] {process_utils.py:190} INFO -     return _get_http_response_with_retries(
[2024-08-13T02:07:09.870+0000] {process_utils.py:190} INFO -   File "/home/***/.local/lib/python3.8/site-packages/mlflow/utils/request_utils.py", line 237, in _get_http_response_with_retries
[2024-08-13T02:07:09.871+0000] {process_utils.py:190} INFO -     return session.request(method, url, allow_redirects=allow_redirects, **kwargs)
[2024-08-13T02:07:09.871+0000] {process_utils.py:190} INFO -   File "/home/***/.local/lib/python3.8/site-packages/requests/sessions.py", line 589, in request
[2024-08-13T02:07:09.872+0000] {process_utils.py:190} INFO -     resp = self.send(prep, **send_kwargs)
[2024-08-13T02:07:09.872+0000] {process_utils.py:190} INFO -   File "/home/***/.local/lib/python3.8/site-packages/requests/sessions.py", line 703, in send
[2024-08-13T02:07:09.872+0000] {process_utils.py:190} INFO -     r = adapter.send(request, **kwargs)
[2024-08-13T02:07:09.872+0000] {process_utils.py:190} INFO -   File "/home/***/.local/lib/python3.8/site-packages/requests/adapters.py", line 519, in send
[2024-08-13T02:07:09.873+0000] {process_utils.py:190} INFO -     raise ConnectionError(e, request=request)
[2024-08-13T02:07:09.873+0000] {process_utils.py:190} INFO - requests.exceptions.ConnectionError: HTTPConnectionPool(host='mlflow', port=5005): Max retries exceeded with url: /api/2.0/mlflow/experiments/get-by-name?experiment_name=Heart+Disease (Caused by NewConnectionError('<urllib3.connection.HTTPConnection object at 0xffff3db188e0>: Failed to establish a new connection: [Errno 111] Connection refused'))
[2024-08-13T02:07:09.873+0000] {process_utils.py:190} INFO - 
[2024-08-13T02:07:09.873+0000] {process_utils.py:190} INFO - During handling of the above exception, another exception occurred:
[2024-08-13T02:07:09.874+0000] {process_utils.py:190} INFO - 
[2024-08-13T02:07:09.874+0000] {process_utils.py:190} INFO - Traceback (most recent call last):
[2024-08-13T02:07:09.874+0000] {process_utils.py:190} INFO -   File "/tmp/venv-calld3mc8wat/script.py", line 129, in <module>
[2024-08-13T02:07:09.874+0000] {process_utils.py:190} INFO -     res = make_dummies_variables(*arg_dict["args"], **arg_dict["kwargs"])
[2024-08-13T02:07:09.875+0000] {process_utils.py:190} INFO -   File "/tmp/venv-calld3mc8wat/script.py", line 110, in make_dummies_variables
[2024-08-13T02:07:09.875+0000] {process_utils.py:190} INFO -     experiment = mlflow.set_experiment("Heart Disease")
[2024-08-13T02:07:09.875+0000] {process_utils.py:190} INFO -   File "/home/***/.local/lib/python3.8/site-packages/mlflow/tracking/fluent.py", line 143, in set_experiment
[2024-08-13T02:07:09.875+0000] {process_utils.py:190} INFO -     experiment = client.get_experiment_by_name(experiment_name)
[2024-08-13T02:07:09.876+0000] {process_utils.py:190} INFO -   File "/home/***/.local/lib/python3.8/site-packages/mlflow/tracking/client.py", line 1240, in get_experiment_by_name
[2024-08-13T02:07:09.876+0000] {process_utils.py:190} INFO -     return self._tracking_client.get_experiment_by_name(name)
[2024-08-13T02:07:09.876+0000] {process_utils.py:190} INFO -   File "/home/***/.local/lib/python3.8/site-packages/mlflow/tracking/_tracking_service/client.py", line 484, in get_experiment_by_name
[2024-08-13T02:07:09.877+0000] {process_utils.py:190} INFO -     return self.store.get_experiment_by_name(name)
[2024-08-13T02:07:09.877+0000] {process_utils.py:190} INFO -   File "/home/***/.local/lib/python3.8/site-packages/mlflow/store/tracking/rest_store.py", line 518, in get_experiment_by_name
[2024-08-13T02:07:09.877+0000] {process_utils.py:190} INFO -     response_proto = self._call_endpoint(GetExperimentByName, req_body)
[2024-08-13T02:07:09.877+0000] {process_utils.py:190} INFO -   File "/home/***/.local/lib/python3.8/site-packages/mlflow/store/tracking/rest_store.py", line 81, in _call_endpoint
[2024-08-13T02:07:09.878+0000] {process_utils.py:190} INFO -     return call_endpoint(self.get_host_creds(), endpoint, method, json_body, response_proto)
[2024-08-13T02:07:09.878+0000] {process_utils.py:190} INFO -   File "/home/***/.local/lib/python3.8/site-packages/mlflow/utils/rest_utils.py", line 357, in call_endpoint
[2024-08-13T02:07:09.878+0000] {process_utils.py:190} INFO -     response = http_request(**call_kwargs)
[2024-08-13T02:07:09.878+0000] {process_utils.py:190} INFO -   File "/home/***/.local/lib/python3.8/site-packages/mlflow/utils/rest_utils.py", line 210, in http_request
[2024-08-13T02:07:09.879+0000] {process_utils.py:190} INFO -     raise MlflowException(f"API request to {url} failed with exception {e}")
[2024-08-13T02:07:09.879+0000] {process_utils.py:190} INFO - mlflow.exceptions.MlflowException: API request to http://mlflow:5005/api/2.0/mlflow/experiments/get-by-name failed with exception HTTPConnectionPool(host='mlflow', port=5005): Max retries exceeded with url: /api/2.0/mlflow/experiments/get-by-name?experiment_name=Heart+Disease (Caused by NewConnectionError('<urllib3.connection.HTTPConnection object at 0xffff3db188e0>: Failed to establish a new connection: [Errno 111] Connection refused'))
[2024-08-13T02:07:10.173+0000] {local_task_job_runner.py:234} INFO - Task exited with return code 0
[2024-08-13T02:07:10.181+0000] {taskinstance.py:3280} INFO - 0 downstream tasks scheduled from follow-on schedule check
